Workbook

Sheet 지역별일일실적 →
A3: 1) 데이터 유실되지 않게 입력 잘 해주시고, 입력 다하셨으면 창을 내려두시는 것을 권장합니다.
A5: 2) 모든 시트의 날짜를 입력할 때 반드시 "월/일"(ex. 7/12) 로 입력하세요. 다른 형태(ex. 2023-7-12 등)로 입력하면 텍스트로 인식하여 수식이 깨져요.

Sheet 2024년12월
A2: 날짜 | B2: 담당 | C2: 상담(거리 및 내방) | G2: 조치 | P2: 조치후 사례관리
B3: 이름 | C3: 정신상담 | D3: 알콜상담 | E3: 기타상담 | F3: 소계 | G3: 자의입원 | H3: 응급입원 | I3: 보호진단 | J3: 시설입소 (노숙영역) | K3: 시설입소 (타복지영역) | L3: 지원주택 | M3: 주거지원 | N3: 물품제공 | O3: 기타 (귀가,외래등) | P3: 외래진료 | Q3: 병원방문 | R3: 주거지방문 | S3: 투약관리 | T3: 기타 (척도, 내방) | U3: 합계
A4: 45627 | B4: 조국일 | F4: =SUM(C4:E4) -> 0 | U4: =sum(G4:T4) -> 0
B5: 최리선 | F5: =SUM(C5:E5) -> 0 | U5: =sum(G5:T5) -> 0
B6: 안영호 | F6: =SUM(C6:E6) -> 0 | U6: =sum(G6:T6) -> 0
B7: 박상준 | E7: 1 | F7: =SUM(C7:E7) -> 1 | T7: 1 | U7: =sum(G7:T7) -> 1
B8: 오강현 | F8: =SUM(C8:E8) -> 0 | U8: =sum(G8:T8) -> 0
B9: 김영민 | C9: 0 | D9: 0 | E9: 0 | F9: =SUM(C9:E9) -> 0 | U9: =sum(G9:T9) -> 0
B10: 임종혁 | F10: =SUM(C10:E10) -> 0 | U10: =sum(G10:T10) -> 0
B11: 마명철 | F11: =SUM(C11:E11) -> 0 | U11: =sum(G11:T11) -> 0
B12: 일일누계 | C12: =SUM(C4:C11) -> 0 | D12: =SUM(D4:D11) -> 0 | E12: =SUM(E4:E11) -> 1 | F12: =SUM(F4:F11) -> 1 | G12: =SUM(G4:G11) -> 0 | H12: =SUM(H4:H11) -> 0 | I12: =SUM(I4:I11) -> 0 | J12: =SUM(J4:J11) -> 0 | ... T12: =SUM(T4:T11) -> 1 | U12: =sum(G12:T12) -> 1 | V12: 구분 | W12: 정신상담 | X12: 알콜상담 | Y12: 기타상담 | Z12: 소계 | AA12: 자의입원 | AB12: 응급입원 | AC12: 보호진단 | AD12: 시설입소(자활, 재활, 요양) | AE12: 시설입소(타복지시설) | AF12: 지원주택 | AG12: 주거지원 | AH12: 물품제공 | AI12: 기타(외래) | AJ12: 외래진료 | AK12: 병원방문 | AL12: 주거지방문 | AM12: 투약관리 | AN12: 기타(척도, 내방)
B13: 총누계 | C13: =SUM('2024년11월'!C313,C12) -> #REF! | D13: =SUM('2024년11월'!D313,D12) -> #REF! | E13: =SUM('2024년11월'!E313,E12) -> #REF! | F13: =SUM('2024년11월'!F313,F12) -> #REF! | G13: =SUM('2024년11월'!G313,G12) -> #REF! | H13: =SUM('2024년11월'!H313,H12) -> #REF! | I13: =SUM('2024년11월'!I313,I12) -> #REF! | J13: =SUM('2024년11월'!J313,J12) -> #REF! | ... U13: =SUM('2024년11월'!U313,U12) -> #REF! | V13: 11월 5주차 | W13: =SUM('2024년11월'!C244:C248,'2024년11월'!C254:C258,'2024년11월'!C264:C268,'2024년11월'!C274:C278,'2024년11월'!C284:C288,'2024년11월'!C294:C298,C4:C8) -> #REF! | X13: =SUM('2024년11월'!D244:D248,'2024년11월'!D254:D258,'2024년11월'!D264:D268,'2024년11월'!D274:D278,'2024년11월'!D284:D288,'2024년11월'!D294:D298,D4:D8) -> #REF! | Y13: =SUM('2024년11월'!E244:E248,'2024년11월'!E254:E258,'2024년11월'!E264:E268,'2024년11월'!E274:E278,'2024년11월'!E284:E288,'2024년11월'!E294:E298,E4:E8) -> #REF! | Z13: =SUM('2024년11월'!F244:F248,'2024년11월'!F254:F258,'2024년11월'!F264:F268,'2024년11월'!F274:F278,'2024년11월'!F284:F288,'2024년11월'!F294:F298,F4:F8) -> #REF! | AA13: =SUM('2024년11월'!G244:G248,'2024년11월'!G254:G258,'2024년11월'!G264:G268,'2024년11월'!G274:G278,'2024년11월'!G284:G288,'2024년11월'!G294:G298,G4:G8) -> #REF! | AB13: =SUM('2024년11월'!H244:H248,'2024년11월'!H254:H258,'2024년11월'!H264:H268,'2024년11월'!H274:H278,'2024년11월'!H284:H288,'2024년11월'!H294:H298,H4:H8) -> #REF! | AC13: =SUM('2024년11월'!I244:I248,'2024년11월'!I254:I258,'2024년11월'!I264:I268,'2024년11월'!I274:I278,'2024년11월'!I284:I288,'2024년11월'!I294:I298,I4:I8) -> #REF! | AD13: =SUM('2024년11월'!J244:J248,'2024년11월'!J254:J258,'2024년11월'!J264:J268,'2024년11월'!J274:J278,'2024년11월'!J284:J288,'2024년11월'!J294:J298,J4:J8) -> #REF! | ... AN13: =SUM('2024년11월'!T244:T248,'2024년11월'!T254:T258,'2024년11월'!T264:T268,'2024년11월'!T274:T278,'2024년11월'!T284:T288,'2024년11월'!T294:T298,T4:T8) -> #REF!
A14: 45628 | B14: 조국일 | C14: 0 | D14: 0 | E14: 0 | F14: =SUM(C14:E14) -> 0 | U14: =sum(G14:T14) -> 0
B15: 최리선 | C15: 4 | F15: =SUM(C15:E15) -> 4 | T15: 4 | U15: =sum(G15:T15) -> 4
B16: 안영호 | C16: 0 | D16: 4 | F16: =SUM(C16:E16) -> 4 | S16: 1 | T16: 3 | U16: =sum(G16:T16) -> 4
B17: 박상준 | C17: 2 | D17: 1 | F17: =SUM(C17:E17) -> 3 | P17: 3 | U17: =sum(G17:T17) -> 3
B18: 오강현 | C18: 6 | D18: 2 | F18: =SUM(C18:E18) -> 8 | P18: 7 | T18: 1 | U18: =sum(G18:T18) -> 8
B19: 김영민 | C19: 1 | D19: 1 | F19: =SUM(C19:E19) -> 2 | P19: 1 | T19: 1 | U19: =sum(G19:T19) -> 2
B20: 임종혁 | C20: 1 | D20: 5 | E20: 2 | F20: =SUM(C20:E20) -> 8 | G20: 1 | P20: 2 | T20: 7 | U20: =sum(G20:T20) -> 10
B21: 마명철 | C21: 0 | D21: 0 | F21: =SUM(C21:E21) -> 0 | U21: =sum(G21:T21) -> 0
B22: 일일누계 | C22: =SUM(C14:C21) -> 14 | D22: =SUM(D14:D21) -> 13 | E22: =SUM(E14:E21) -> 2 | F22: =SUM(F14:F21) -> 29 | G22: =SUM(G14:G21) -> 1 | H22: =SUM(H14:H21) -> 0 | I22: =SUM(I14:I21) -> 0 | J22: =SUM(J14:J21) -> 0 | ... T22: =SUM(T14:T21) -> 16 | U22: =sum(G22:T22) -> 31
B23: 총누계 | C23: =C13+C22 -> #REF! | D23: =D13+D22 -> #REF! | E23: =E13+E22 -> #REF! | F23: =F13+F22 -> #REF! | G23: =G13+G22 -> #REF! | H23: =H13+H22 -> #REF! | I23: =I13+I22 -> #REF! | J23: =J13+J22 -> #REF! | ... T23: =T13+T22 -> #REF! | U23: =sum(G23:T23) -> #REF!
A24: 45629 | B24: 조국일 | C24: 1 | D24: 0 | E24: 0 | F24: =SUM(C24:E24) -> 1 | G24: 1 | U24: =sum(G24:T24) -> 1
B25: 최리선 | C25: 4 | F25: =SUM(C25:E25) -> 4 | S25: 2 | T25: 3 | U25: =sum(G25:T25) -> 5
B26: 안영호 | C26: 1 | D26: 3 | F26: =SUM(C26:E26) -> 4 | U26: =sum(G26:T26) -> 0
B27: 박상준 | C27: 5 | D27: 1 | F27: =SUM(C27:E27) -> 6 | N27: 5 | P27: 1 | U27: =sum(G27:T27) -> 6
B28: 오강현 | C28: 5 | D28: 1 | F28: =SUM(C28:E28) -> 6 | P28: 6 | U28: =sum(G28:T28) -> 6
B29: 김영민 | D29: 1 | F29: =SUM(C29:E29) -> 1 | T29: 1 | U29: =sum(G29:T29) -> 1
B30: 임종혁 | C30: 1 | D30: 1 | F30: =SUM(C30:E30) -> 2 | I30: 1 | T30: 2 | U30: =sum(G30:T30) -> 3
B31: 마명철 | C31: 0 | D31: 0 | F31: =SUM(C31:E31) -> 0 | U31: =sum(G31:T31) -> 0
B32: 일일누계 | C32: =SUM(C24:C31) -> 17 | D32: =SUM(D24:D31) -> 7 | E32: =SUM(E24:E31) -> 0 | F32: =SUM(F24:F31) -> 24 | G32: =SUM(G24:G31) -> 1 | H32: =SUM(H24:H31) -> 0 | I32: =SUM(I24:I31) -> 1 | J32: =SUM(J24:J31) -> 0 | ... T32: =SUM(T24:T31) -> 6 | U32: =sum(G32:T32) -> 22
B33: 총누계 | C33: =C23+C32 -> #REF! | D33: =D23+D32 -> #REF! | E33: =E23+E32 -> #REF! | F33: =F23+F32 -> #REF! | G33: =G23+G32 -> #REF! | H33: =H23+H32 -> #REF! | I33: =I23+I32 -> #REF! | J33: =J23+J32 -> #REF! | ... T33: =T23+T32 -> #REF! | U33: =sum(G33:T33) -> #REF!
A34: 45630 | B34: 조국일 | D34: 2 | F34: =SUM(C34:E34) -> 2 | T34: 2 | U34: =sum(G34:T34) -> 2
B35: 최리선 | C35: 5 | F35: =SUM(C35:E35) -> 5 | T35: 5 | U35: =sum(G35:T35) -> 5
B36: 안영호 | C36: 1 | F36: =SUM(C36:E36) -> 1 | G36: 1 | P36: 1 | U36: =sum(G36:T36) -> 2
B37: 박상준 | D37: 2 | F37: =SUM(C37:E37) -> 2 | P37: 2 | T37: 1 | U37: =sum(G37:T37) -> 3
B38: 오강현 | C38: 6 | D38: 1 | F38: =SUM(C38:E38) -> 7 | P38: 6 | T38: 1 | U38: =sum(G38:T38) -> 7
B39: 김영민 | C39: 3 | D39: 2 | F39: =SUM(C39:E39) -> 5 | P39: 2 | T39: 3 | U39: =sum(G39:T39) -> 5
B40: 임종혁 | C40: 2 | D40: 3 | F40: =SUM(C40:E40) -> 5 | I40: 1 | P40: 2 | T40: 4 | U40: =sum(G40:T40) -> 7
B41: 마명철 | C41: 0 | D41: 0 | F41: =SUM(C41:E41) -> 0 | U41: =sum(G41:T41) -> 0
...

Sheet 양식
A2: 날짜 | B2: 담당 | C2: 상담(거리 및 내방) | G2: 조치 | P2: 조치후 사례관리
B3: 이름 | C3: 정신상담 | D3: 알콜상담 | E3: 기타상담 | F3: 소계 | G3: 자의입원 | H3: 응급입원 | I3: 보호진단 | J3: 시설입소 (노숙영역) | K3: 시설입소 (타복지영역) | L3: 지원주택 | M3: 주거지원 | N3: 물품제공 | O3: 기타 (귀가,외래등) | P3: 외래진료 | Q3: 병원방문 | R3: 주거지방문 | S3: 투약관리 | T3: 기타 (척도, 내방) | U3: 합계
A4: 46054 | B4: 조국일 | F4: =SUM(C4:E4) -> 0 | U4: =sum(G4:T4) -> 0
B5: 최리선 | F5: =SUM(C5:E5) -> 0 | U5: =sum(G5:T5) -> 0
B6: 안영호 | F6: =SUM(C6:E6) -> 0 | U6: =sum(G6:T6) -> 0
B7: 박상준 | F7: =SUM(C7:E7) -> 0 | U7: =sum(G7:T7) -> 0
B8: 김영민 | F8: =SUM(C8:E8) -> 0 | U8: =sum(G8:T8) -> 0
B9: 임종혁 | F9: =SUM(C9:E9) -> 0 | U9: =sum(G9:T9) -> 0
B10: 마명철 | F10: =SUM(C10:E10) -> 0 | U10: =sum(G10:T10) -> 0
B11: 일일누계 | C11: =SUM(C4:C10) -> 0 | D11: =SUM(D4:D10) -> 0 | E11: =SUM(E4:E10) -> 0 | F11: =SUM(F4:F10) -> 0 | G11: =SUM(G4:G10) -> 0 | H11: =SUM(H4:H10) -> 0 | I11: =SUM(I4:I10) -> 0 | J11: =SUM(J4:J10) -> 0 | ... T11: =SUM(T4:T10) -> 0 | U11: =sum(G11:T11) -> 0
B12: 총누계 | C12: =C11 -> 0 | D12: =D11 -> 0 | E12: =E11 -> 0 | F12: =F11 -> 0 | G12: =G11 -> 0 | H12: =H11 -> 0 | I12: =I11 -> 0 | J12: =J11 -> 0 | ... U12: =U11 -> 0
A13: 46055 | B13: 조국일 | F13: =SUM(C13:E13) -> 0 | U13: =sum(G13:T13) -> 0
B14: 최리선 | F14: =SUM(C14:E14) -> 0 | U14: =sum(G14:T14) -> 0
B15: 안영호 | F15: =SUM(C15:E15) -> 0 | U15: =sum(G15:T15) -> 0
B16: 박상준 | F16: =SUM(C16:E16) -> 0 | U16: =sum(G16:T16) -> 0
B17: 김영민 | F17: =SUM(C17:E17) -> 0 | U17: =sum(G17:T17) -> 0
B18: 임종혁 | F18: =SUM(C18:E18) -> 0 | U18: =sum(G18:T18) -> 0
B19: 마명철 | F19: =SUM(C19:E19) -> 0 | U19: =sum(G19:T19) -> 0
B20: 일일누계 | C20: =SUM(C13:C19) -> 0 | D20: =SUM(D13:D19) -> 0 | E20: =SUM(E13:E19) -> 0 | F20: =SUM(F13:F19) -> 0 | G20: =SUM(G13:G19) -> 0 | H20: =SUM(H13:H19) -> 0 | I20: =SUM(I13:I19) -> 0 | J20: =SUM(J13:J19) -> 0 | ... T20: =SUM(T13:T19) -> 0 | U20: =sum(G20:T20) -> 0
B21: 총누계 | C21: =C12+C20 -> 0 | D21: =D12+D20 -> 0 | E21: =E12+E20 -> 0 | F21: =F12+F20 -> 0 | G21: =G12+G20 -> 0 | H21: =H12+H20 -> 0 | I21: =I12+I20 -> 0 | J21: =J12+J20 -> 0 | ... U21: =U12+U20 -> 0
A22: 46056 | B22: 조국일 | F22: =SUM(C22:E22) -> 0 | U22: =sum(G22:T22) -> 0
B23: 최리선 | F23: =SUM(C23:E23) -> 0 | U23: =sum(G23:T23) -> 0
B24: 안영호 | F24: =SUM(C24:E24) -> 0 | U24: =sum(G24:T24) -> 0
B25: 박상준 | F25: =SUM(C25:E25) -> 0 | U25: =sum(G25:T25) -> 0
B26: 김영민 | F26: =SUM(C26:E26) -> 0 | U26: =sum(G26:T26) -> 0
B27: 임종혁 | F27: =SUM(C27:E27) -> 0 | U27: =sum(G27:T27) -> 0
B28: 마명철 | C28: 0 | D28: 0 | F28: =SUM(C28:E28) -> 0 | U28: =sum(G28:T28) -> 0
B29: 일일누계 | C29: =SUM(C22:C28) -> 0 | D29: =SUM(D22:D28) -> 0 | E29: =SUM(E22:E28) -> 0 | F29: =SUM(F22:F28) -> 0 | G29: =SUM(G22:G28) -> 0 | H29: =SUM(H22:H28) -> 0 | I29: =SUM(I22:I28) -> 0 | J29: =SUM(J22:J28) -> 0 | ... T29: =SUM(T22:T28) -> 0 | U29: =sum(G29:T29) -> 0
B30: 총누계 | C30: =C21+C29 -> 0 | D30: =D21+D29 -> 0 | E30: =E21+E29 -> 0 | F30: =F21+F29 -> 0 | G30: =G21+G29 -> 0 | H30: =H21+H29 -> 0 | I30: =I21+I29 -> 0 | J30: =J21+J29 -> 0 | ... U30: =U21+U29 -> 0
A31: 46057 | B31: 조국일 | F31: =SUM(C31:E31) -> 0 | U31: =sum(G31:T31) -> 0
B32: 최리선 | F32: =SUM(C32:E32) -> 0 | U32: =sum(G32:T32) -> 0
B33: 안영호 | F33: =SUM(C33:E33) -> 0 | U33: =sum(G33:T33) -> 0
B34: 박상준 | F34: =SUM(C34:E34) -> 0 | U34: =sum(G34:T34) -> 0
B35: 김영민 | F35: =SUM(C35:E35) -> 0 | U35: =sum(G35:T35) -> 0
B36: 임종혁 | F36: =SUM(C36:E36) -> 0 | U36: =sum(G36:T36) -> 0 | W36: 62 | X36: 20 | Y36: 0 | Z36: 82 | AA36: 2 | AB36: 0 | AC36: 1 | AD36: 0 | AE36: 0 | AF36: 8 | AG36: 0 | AH36: 0 | AI36: 1 | AJ36: 46 | AK36: 0 | AL36: 16 | AM36: 0 | AN36: 8
B37: 마명철 | F37: =SUM(C37:E37) -> 0 | U37: =sum(G37:T37) -> 0 | W37: 35 | X37: 16 | Y37: 0 | Z37: 51 | AA37: 2 | AB37: 0 | AC37: 0 | AD37: 1 | AE37: 0 | AF37: 0 | AG37: 0 | AH37: 0 | AI37: 3 | AJ37: 21 | AK37: 0 | AL37: 25 | AM37: 0 | AN37: 2
B38: 일일누계 | C38: =SUM(C31:C37) -> 0 | D38: =SUM(D31:D37) -> 0 | E38: =SUM(E31:E37) -> 0 | F38: =SUM(F31:F37) -> 0 | G38: =SUM(G31:G37) -> 0 | H38: =SUM(H31:H37) -> 0 | I38: =SUM(I31:I37) -> 0 | J38: =SUM(J31:J37) -> 0 | ... T38: =SUM(T31:T37) -> 0 | U38: =sum(G38:T38) -> 0 | V38: 구분 | W38: 정신상담 | X38: 알콜상담 | Y38: 기타상담 | Z38: 소계 | AA38: 자의입원 | AB38: 응급입원 | AC38: 보호진단 | AD38: 시설입소(자활, 재활, 요양) | AE38: 시설입소(타복지시설) | AF38: 지원주택 | AG38: 주거지원 | AH38: 물품제공 | AI38: 기타(외래) | AJ38: 외래진료 | AK38: 병원방문 | AL38: 주거지방문 | AM38: 투약관리 | AN38: 기타(척도, 내방)
B39: 총누계 | C39: =C30+C38 -> 0 | D39: =D30+D38 -> 0 | E39: =E30+E38 -> 0 | F39: =F30+F38 -> 0 | G39: =G30+G38 -> 0 | H39: =H30+H38 -> 0 | I39: =I30+I38 -> 0 | J39: =J30+J38 -> 0 | ... U39: =U30+U38 -> 0 | V39: 1월 1주차 | W39: =W36+W37 -> 97 | X39: =X36+X37 -> 36 | Y39: =Y36+Y37 -> 0 | Z39: =Z36+Z37 -> 133 | AA39: =AA36+AA37 -> 4 | AB39: =AB36+AB37 -> 0 | AC39: =AC36+AC37 -> 1 | AD39: =AD36+AD37 -> 1 | ... AN39: =AN36+AN37 -> 10
A40: 46058 | B40: 조국일 | F40: =SUM(C40:E40) -> 0 | U40: =sum(G40:T40) -> 0
B41: 최리선 | F41: =SUM(C41:E41) -> 0 | U41: =sum(G41:T41) -> 0
...

Sheet 기준
A1: 구분
A2: 상담 | B2: 자의입원 | C2: 자의입원
A3: 서비스 | B3: 기타

Sheet 시트55
A1: OR(USERROLE() = "Admin", [이메일] = USEREMAIL())
A3: 앱시트 슬라이스에서 만약 관리자(Admin)는 모든 데이터를 보고, 일반 사용자는 자기 것만 보게 하고 싶다면? 쉽게 순서대로 알려줘

Sheet 2026년1월
A2: 날짜 | B2: 담당 | C2: 상담(거리 및 내방) | G2: 조치 | P2: 조치후 사례관리
B3: 이름 | C3: 정신상담 | D3: 알콜상담 | E3: 기타상담 | F3: 소계 | G3: 자의입원 | H3: 응급입원 | I3: 보호진단 | J3: 시설입소 (노숙영역) | K3: 시설입소 (타복지영역) | L3: 지원주택 | M3: 주거지원 | N3: 물품제공 | O3: 기타 (귀가,외래등) | P3: 외래진료 | Q3: 병원방문 | R3: 주거지방문 | S3: 투약관리 | T3: 기타 (척도, 내방) | U3: 합계
A4: 46023 | B4: 조국일 | F4: =SUM(C4:E4) -> 0 | U4: =sum(G4:T4) -> 0
B5: 최리선 | F5: =SUM(C5:E5) -> 0 | U5: =sum(G5:T5) -> 0
B6: 안영호 | F6: =SUM(C6:E6) -> 0 | U6: =sum(G6:T6) -> 0
B7: 박상준 | F7: =SUM(C7:E7) -> 0 | U7: =sum(G7:T7) -> 0
B8: 김영민 | F8: =SUM(C8:E8) -> 0 | U8: =sum(G8:T8) -> 0
B9: 임종혁 | F9: =SUM(C9:E9) -> 0 | U9: =sum(G9:T9) -> 0
B10: 마명철 | F10: =SUM(C10:E10) -> 0 | U10: =sum(G10:T10) -> 0
B11: 일일누계 | C11: =SUM(C4:C10) -> 0 | D11: =SUM(D4:D10) -> 0 | E11: =SUM(E4:E10) -> 0 | F11: =SUM(F4:F10) -> 0 | G11: =SUM(G4:G10) -> 0 | H11: =SUM(H4:H10) -> 0 | I11: =SUM(I4:I10) -> 0 | J11: =SUM(J4:J10) -> 0 | ... T11: =SUM(T4:T10) -> 0 | U11: =sum(G11:T11) -> 0
B12: 총누계 | C12: =C11 -> 0 | D12: =D11 -> 0 | E12: =E11 -> 0 | F12: =F11 -> 0 | G12: =G11 -> 0 | H12: =H11 -> 0 | I12: =I11 -> 0 | J12: =J11 -> 0 | ... U12: =U11 -> 0
A13: 46024 | B13: 조국일 | C13: 3 | D13: 1 | F13: =SUM(C13:E13) -> 4 | G13: 1 | J13: 1 | P13: 2 | U13: =sum(G13:T13) -> 4
B14: 최리선 | C14: 1 | F14: =SUM(C14:E14) -> 1 | T14: 1 | U14: =sum(G14:T14) -> 1
B15: 안영호 | C15: 12 | D15: 4 | F15: =SUM(C15:E15) -> 16 | O15: 1 | P15: 14 | T15: 1 | U15: =sum(G15:T15) -> 16
B16: 박상준 | F16: =SUM(C16:E16) -> 0 | U16: =sum(G16:T16) -> 0
B17: 김영민 | C17: 19 | D17: 11 | F17: =SUM(C17:E17) -> 30 | O17: 2 | P17: 5 | R17: 25 | U17: =sum(G17:T17) -> 32
B18: 임종혁 | C18: 4 | D18: 2 | F18: =SUM(C18:E18) -> 6 | P18: 2 | T18: 6 | U18: =sum(G18:T18) -> 8
B19: 마명철 | F19: =SUM(C19:E19) -> 0 | U19: =sum(G19:T19) -> 0
B20: 일일누계 | C20: =SUM(C13:C19) -> 39 | D20: =SUM(D13:D19) -> 18 | E20: =SUM(E13:E19) -> 0 | F20: =SUM(F13:F19) -> 57 | G20: =SUM(G13:G19) -> 1 | H20: =SUM(H13:H19) -> 0 | I20: =SUM(I13:I19) -> 0 | J20: =SUM(J13:J19) -> 1 | ... T20: =SUM(T13:T19) -> 8 | U20: =sum(G20:T20) -> 61
B21: 총누계 | C21: =C12+C20 -> 39 | D21: =D12+D20 -> 18 | E21: =E12+E20 -> 0 | F21: =F12+F20 -> 57 | G21: =G12+G20 -> 1 | H21: =H12+H20 -> 0 | I21: =I12+I20 -> 0 | J21: =J12+J20 -> 1 | ... U21: =U12+U20 -> 61
A22: 46025 | B22: 조국일 | F22: =SUM(C22:E22) -> 0 | U22: =sum(G22:T22) -> 0
B23: 최리선 | F23: =SUM(C23:E23) -> 0 | U23: =sum(G23:T23) -> 0
B24: 안영호 | C24: 3 | F24: =SUM(C24:E24) -> 3 | P24: 3 | U24: =sum(G24:T24) -> 3
B25: 박상준 | C25: 5 | D25: 2 | F25: =SUM(C25:E25) -> 7 | P25: 7 | U25: =sum(G25:T25) -> 7
B26: 김영민 | F26: =SUM(C26:E26) -> 0 | U26: =sum(G26:T26) -> 0
B27: 임종혁 | F27: =SUM(C27:E27) -> 0 | U27: =sum(G27:T27) -> 0
B28: 마명철 | C28: 0 | D28: 0 | F28: =SUM(C28:E28) -> 0 | U28: =sum(G28:T28) -> 0
B29: 일일누계 | C29: =SUM(C22:C28) -> 8 | D29: =SUM(D22:D28) -> 2 | E29: =SUM(E22:E28) -> 0 | F29: =SUM(F22:F28) -> 10 | G29: =SUM(G22:G28) -> 0 | H29: =SUM(H22:H28) -> 0 | I29: =SUM(I22:I28) -> 0 | J29: =SUM(J22:J28) -> 0 | ... T29: =SUM(T22:T28) -> 0 | U29: =sum(G29:T29) -> 10
B30: 총누계 | C30: =C21+C29 -> 47 | D30: =D21+D29 -> 20 | E30: =E21+E29 -> 0 | F30: =F21+F29 -> 67 | G30: =G21+G29 -> 1 | H30: =H21+H29 -> 0 | I30: =I21+I29 -> 0 | J30: =J21+J29 -> 1 | ... U30: =U21+U29 -> 71
A31: 46026 | B31: 조국일 | F31: =SUM(C31:E31) -> 0 | U31: =sum(G31:T31) -> 0
B32: 최리선 | F32: =SUM(C32:E32) -> 0 | U32: =sum(G32:T32) -> 0
B33: 안영호 | F33: =SUM(C33:E33) -> 0 | U33: =sum(G33:T33) -> 0
B34: 박상준 | F34: =SUM(C34:E34) -> 0 | U34: =sum(G34:T34) -> 0
B35: 김영민 | F35: =SUM(C35:E35) -> 0 | U35: =sum(G35:T35) -> 0
B36: 임종혁 | F36: =SUM(C36:E36) -> 0 | U36: =sum(G36:T36) -> 0 | W36: 62 | X36: 20 | Y36: 0 | Z36: 82 | AA36: 2 | AB36: 0 | AC36: 1 | AD36: 0 | AE36: 0 | AF36: 8 | AG36: 0 | AH36: 0 | AI36: 1 | AJ36: 46 | AK36: 0 | AL36: 16 | AM36: 0 | AN36: 8
B37: 마명철 | F37: =SUM(C37:E37) -> 0 | U37: =sum(G37:T37) -> 0 | W37: 35 | X37: 16 | Y37: 0 | Z37: 51 | AA37: 2 | AB37: 0 | AC37: 0 | AD37: 1 | AE37: 0 | AF37: 0 | AG37: 0 | AH37: 0 | AI37: 3 | AJ37: 21 | AK37: 0 | AL37: 25 | AM37: 0 | AN37: 2
B38: 일일누계 | C38: =SUM(C31:C37) -> 0 | D38: =SUM(D31:D37) -> 0 | E38: =SUM(E31:E37) -> 0 | F38: =SUM(F31:F37) -> 0 | G38: =SUM(G31:G37) -> 0 | H38: =SUM(H31:H37) -> 0 | I38: =SUM(I31:I37) -> 0 | J38: =SUM(J31:J37) -> 0 | ... T38: =SUM(T31:T37) -> 0 | U38: =sum(G38:T38) -> 0 | V38: 구분 | W38: 정신상담 | X38: 알콜상담 | Y38: 기타상담 | Z38: 소계 | AA38: 자의입원 | AB38: 응급입원 | AC38: 보호진단 | AD38: 시설입소(자활, 재활, 요양) | AE38: 시설입소(타복지시설) | AF38: 지원주택 | AG38: 주거지원 | AH38: 물품제공 | AI38: 기타(외래) | AJ38: 외래진료 | AK38: 병원방문 | AL38: 주거지방문 | AM38: 투약관리 | AN38: 기타(척도, 내방)
B39: 총누계 | C39: =C30+C38 -> 47 | D39: =D30+D38 -> 20 | E39: =E30+E38 -> 0 | F39: =F30+F38 -> 67 | G39: =G30+G38 -> 1 | H39: =H30+H38 -> 0 | I39: =I30+I38 -> 0 | J39: =J30+J38 -> 1 | ... U39: =U30+U38 -> 71 | V39: 1월 1주차 | W39: =W36+W37 -> 97 | X39: =X36+X37 -> 36 | Y39: =Y36+Y37 -> 0 | Z39: =Z36+Z37 -> 133 | AA39: =AA36+AA37 -> 4 | AB39: =AB36+AB37 -> 0 | AC39: =AC36+AC37 -> 1 | AD39: =AD36+AD37 -> 1 | ... AN39: =AN36+AN37 -> 10
A40: 46027 | B40: 조국일 | C40: 2 | F40: =SUM(C40:E40) -> 2 | H40: 1 | P40: 1 | U40: =sum(G40:T40) -> 2
B41: 최리선 | C41: 2 | D41: 1 | F41: =SUM(C41:E41) -> 3 | T41: 3 | U41: =sum(G41:T41) -> 3
...

Sheet 2026년2월
A2: 날짜 | B2: 담당 | C2: 상담(거리 및 내방) | G2: 조치 | P2: 조치후 사례관리
B3: 이름 | C3: 정신상담 | D3: 알콜상담 | E3: 기타상담 | F3: 소계 | G3: 자의입원 | H3: 응급입원 | I3: 보호진단 | J3: 시설입소 (노숙영역) | K3: 시설입소 (타복지영역) | L3: 지원주택 | M3: 주거지원 | N3: 물품제공 | O3: 기타 (귀가,외래등) | P3: 외래진료 | Q3: 병원방문 | R3: 주거지방문 | S3: 투약관리 | T3: 기타 (척도, 내방) | U3: 합계
A4: 46054 | B4: 조국일 | F4: =SUM(C4:E4) -> 0 | U4: =sum(G4:T4) -> 0
B5: 최리선 | F5: =SUM(C5:E5) -> 0 | U5: =sum(G5:T5) -> 0
B6: 안영호 | F6: =SUM(C6:E6) -> 0 | U6: =sum(G6:T6) -> 0
B7: 박상준 | F7: =SUM(C7:E7) -> 0 | U7: =sum(G7:T7) -> 0
B8: 김영민 | F8: =SUM(C8:E8) -> 0 | U8: =sum(G8:T8) -> 0
B9: 임종혁 | F9: =SUM(C9:E9) -> 0 | U9: =sum(G9:T9) -> 0
B10: 마명철 | F10: =SUM(C10:E10) -> 0 | U10: =sum(G10:T10) -> 0
B11: 일일누계 | C11: =SUM(C4:C10) -> 0 | D11: =SUM(D4:D10) -> 0 | E11: =SUM(E4:E10) -> 0 | F11: =SUM(F4:F10) -> 0 | G11: =SUM(G4:G10) -> 0 | H11: =SUM(H4:H10) -> 0 | I11: =SUM(I4:I10) -> 0 | J11: =SUM(J4:J10) -> 0 | ... T11: =SUM(T4:T10) -> 0 | U11: =sum(G11:T11) -> 0 | V11: 구분 | W11: 정신상담 | X11: 알콜상담 | Y11: 기타상담 | Z11: 소계 | AA11: 자의입원 | AB11: 응급입원 | AC11: 보호진단 | AD11: 시설입소(자활, 재활, 요양) | AE11: 시설입소(타복지시설) | AF11: 지원주택 | AG11: 주거지원 | AH11: 물품제공 | AI11: 기타(외래) | AJ11: 외래진료 | AK11: 병원방문 | AL11: 주거지방문 | AM11: 투약관리 | AN11: 기타(척도, 내방)
B12: 총누계 | C12: =C11+'2026년1월'!C282 -> 583 | D12: =D11+'2026년1월'!D282 -> 229 | E12: =E11+'2026년1월'!E282 -> 2 | F12: =F11+'2026년1월'!F282 -> 814 | G12: =G11+'2026년1월'!G282 -> 12 | H12: =H11+'2026년1월'!H282 -> 8 | I12: =I11+'2026년1월'!I282 -> 6 | J12: =J11+'2026년1월'!J282 -> 1 | ... U12: =U11+'2026년1월'!U282 -> 894 | V12: 2월 1주차 | W12: =SUM('2026년1월'!C229:C233,'2026년1월'!C238:C242,'2026년1월'!C247:C251,'2026년1월'!C256:C260,'2026년1월'!C265:C269,'2026년1월'!C274:C278,C4:C8) -> 132 | X12: =SUM('2026년1월'!D229:D233,'2026년1월'!D238:D242,'2026년1월'!D247:D251,'2026년1월'!D256:D260,'2026년1월'!D265:D269,'2026년1월'!D274:D278,D4:D8) -> 48 | Y12: =SUM('2026년1월'!E229:E233,'2026년1월'!E238:E242,'2026년1월'!E247:E251,'2026년1월'!E256:E260,'2026년1월'!E265:E269,'2026년1월'!E274:E278,E4:E8) -> 0 | Z12: =SUM('2026년1월'!F229:F233,'2026년1월'!F238:F242,'2026년1월'!F247:F251,'2026년1월'!F256:F260,'2026년1월'!F265:F269,'2026년1월'!F274:F278,F4:F8) -> 180 | AA12: =SUM('2026년1월'!G229:G233,'2026년1월'!G238:G242,'2026년1월'!G247:G251,'2026년1월'!G256:G260,'2026년1월'!G265:G269,'2026년1월'!G274:G278,G4:G8) -> 0 | AB12: =SUM('2026년1월'!H229:H233,'2026년1월'!H238:H242,'2026년1월'!H247:H251,'2026년1월'!H256:H260,'2026년1월'!H265:H269,'2026년1월'!H274:H278,H4:H8) -> 4 | AC12: =SUM('2026년1월'!I229:I233,'2026년1월'!I238:I242,'2026년1월'!I247:I251,'2026년1월'!I256:I260,'2026년1월'!I265:I269,'2026년1월'!I274:I278,I4:I8) -> 2 | AD12: =SUM('2026년1월'!J229:J233,'2026년1월'!J238:J242,'2026년1월'!J247:J251,'2026년1월'!J256:J260,'2026년1월'!J265:J269,'2026년1월'!J274:J278,J4:J8) -> 0 | ... AN12: =SUM('2026년1월'!T229:T233,'2026년1월'!T238:T242,'2026년1월'!T247:T251,'2026년1월'!T256:T260,'2026년1월'!T265:T269,'2026년1월'!T274:T278,T4:T8) -> 27
A13: 46055 | B13: 조국일 | C13: 1 | F13: =SUM(C13:E13) -> 1 | S13: 1 | U13: =sum(G13:T13) -> 1
B14: 최리선 | C14: 1 | D14: 1 | F14: =SUM(C14:E14) -> 2 | P14: 1 | T14: 1 | U14: =sum(G14:T14) -> 2
B15: 안영호 | F15: =SUM(C15:E15) -> 0 | U15: =sum(G15:T15) -> 0
B16: 박상준 | C16: 18 | D16: 6 | F16: =SUM(C16:E16) -> 24 | P16: 23 | T16: 1 | U16: =sum(G16:T16) -> 24
B17: 김영민 | F17: =SUM(C17:E17) -> 0 | U17: =sum(G17:T17) -> 0
B18: 임종혁 | C18: 1 | D18: 1 | F18: =SUM(C18:E18) -> 2 | T18: 2 | U18: =sum(G18:T18) -> 2
B19: 마명철 | C19: 0 | D19: 0 | F19: =SUM(C19:E19) -> 0 | U19: =sum(G19:T19) -> 0
B20: 일일누계 | C20: =SUM(C13:C19) -> 21 | D20: =SUM(D13:D19) -> 8 | E20: =SUM(E13:E19) -> 0 | F20: =SUM(F13:F19) -> 29 | G20: =SUM(G13:G19) -> 0 | H20: =SUM(H13:H19) -> 0 | I20: =SUM(I13:I19) -> 0 | J20: =SUM(J13:J19) -> 0 | ... T20: =SUM(T13:T19) -> 4 | U20: =sum(G20:T20) -> 29
B21: 총누계 | C21: =C12+C20 -> 604 | D21: =D12+D20 -> 237 | E21: =E12+E20 -> 2 | F21: =F12+F20 -> 843 | G21: =G12+G20 -> 12 | H21: =H12+H20 -> 8 | I21: =I12+I20 -> 6 | J21: =J12+J20 -> 1 | ... U21: =U12+U20 -> 923
A22: 46056 | B22: 조국일 | C22: 0 | D22: 0 | E22: 0 | F22: =SUM(C22:E22) -> 0 | U22: =sum(G22:T22) -> 0
B23: 최리선 | C23: 14 | D23: 4 | F23: =SUM(C23:E23) -> 18 | P23: 15 | T23: 3 | U23: =sum(G23:T23) -> 18
B24: 안영호 | C24: 3 | D24: 1 | F24: =SUM(C24:E24) -> 4 | G24: 1 | J24: 1 | P24: 1 | T24: 1 | U24: =sum(G24:T24) -> 4
B25: 박상준 | C25: 4 | F25: =SUM(C25:E25) -> 4 | L25: 1 | N25: 3 | U25: =sum(G25:T25) -> 4
B26: 김영민 | C26: 2 | F26: =SUM(C26:E26) -> 2 | I26: 1 | T26: 1 | U26: =sum(G26:T26) -> 2
B27: 임종혁 | C27: 3 | D27: 4 | F27: =SUM(C27:E27) -> 7 | P27: 1 | R27: 2 | T27: 6 | U27: =sum(G27:T27) -> 9
B28: 마명철 | C28: 0 | D28: 0 | F28: =SUM(C28:E28) -> 0 | U28: =sum(G28:T28) -> 0
B29: 일일누계 | C29: =SUM(C22:C28) -> 26 | D29: =SUM(D22:D28) -> 9 | E29: =SUM(E22:E28) -> 0 | F29: =SUM(F22:F28) -> 35 | G29: =SUM(G22:G28) -> 1 | H29: =SUM(H22:H28) -> 0 | I29: =SUM(I22:I28) -> 1 | J29: =SUM(J22:J28) -> 1 | ... T29: =SUM(T22:T28) -> 11 | U29: =sum(G29:T29) -> 37
B30: 총누계 | C30: =C21+C29 -> 630 | D30: =D21+D29 -> 246 | E30: =E21+E29 -> 2 | F30: =F21+F29 -> 878 | G30: =G21+G29 -> 13 | H30: =H21+H29 -> 8 | I30: =I21+I29 -> 7 | J30: =J21+J29 -> 2 | ... U30: =U21+U29 -> 960
A31: 46057 | B31: 조국일 | C31: 1 | D31: 2 | F31: =SUM(C31:E31) -> 3 | T31: 3 | U31: =sum(G31:T31) -> 3
B32: 최리선 | C32: 16 | D32: 6 | F32: =SUM(C32:E32) -> 22 | P32: 18 | T32: 4 | U32: =sum(G32:T32) -> 22
B33: 안영호 | C33: 2 | D33: 1 | F33: =SUM(C33:E33) -> 3 | T33: 3 | U33: =sum(G33:T33) -> 3
B34: 박상준 | F34: =SUM(C34:E34) -> 0 | U34: =sum(G34:T34) -> 0
B35: 김영민 | C35: 1 | D35: 1 | F35: =SUM(C35:E35) -> 2 | T35: 2 | U35: =sum(G35:T35) -> 2
B36: 임종혁 | C36: 4 | D36: 2 | F36: =SUM(C36:E36) -> 6 | P36: 3 | R36: 1 | T36: 7 | U36: =sum(G36:T36) -> 11
B37: 마명철 | C37: 1 | F37: =SUM(C37:E37) -> 1 | O37: 1 | U37: =sum(G37:T37) -> 1
B38: 일일누계 | C38: =SUM(C31:C37) -> 25 | D38: =SUM(D31:D37) -> 12 | E38: =SUM(E31:E37) -> 0 | F38: =SUM(F31:F37) -> 37 | G38: =SUM(G31:G37) -> 0 | H38: =SUM(H31:H37) -> 0 | I38: =SUM(I31:I37) -> 0 | J38: =SUM(J31:J37) -> 0 | ... T38: =SUM(T31:T37) -> 19 | U38: =sum(G38:T38) -> 42
B39: 총누계 | C39: =C30+C38 -> 655 | D39: =D30+D38 -> 258 | E39: =E30+E38 -> 2 | F39: =F30+F38 -> 915 | G39: =G30+G38 -> 13 | H39: =H30+H38 -> 8 | I39: =I30+I38 -> 7 | J39: =J30+J38 -> 2 | ... U39: =U30+U38 -> 1002
A40: 46058 | B40: 조국일 | F40: =SUM(C40:E40) -> 0 | U40: =sum(G40:T40) -> 0
B41: 최리선 | D41: 2 | F41: =SUM(C41:E41) -> 2 | G41: 1 | U41: =sum(G41:T41) -> 1
...

Sheet 2026년3월
A2: 날짜 | B2: 담당 | C2: 상담(거리 및 내방) | G2: 조치 | P2: 조치후 사례관리
B3: 이름 | C3: 정신상담 | D3: 알콜상담 | E3: 기타상담 | F3: 소계 | G3: 자의입원 | H3: 응급입원 | I3: 보호진단 | J3: 시설입소 (노숙영역) | K3: 시설입소 (타복지영역) | L3: 지원주택 | M3: 주거지원 | N3: 물품제공 | O3: 기타 (귀가,외래등) | P3: 외래진료 | Q3: 병원방문 | R3: 주거지방문 | S3: 투약관리 | T3: 기타 (척도, 내방) | U3: 합계
A4: 46082 | B4: 조국일 | F4: =SUM(C4:E4) -> 0 | U4: =sum(G4:T4) -> 0
B5: 최리선 | F5: =SUM(C5:E5) -> 0 | U5: =sum(G5:T5) -> 0
B6: 안영호 | F6: =SUM(C6:E6) -> 0 | U6: =sum(G6:T6) -> 0
B7: 박상준 | F7: =SUM(C7:E7) -> 0 | U7: =sum(G7:T7) -> 0
B8: 김영민 | F8: =SUM(C8:E8) -> 0 | U8: =sum(G8:T8) -> 0
B9: 임종혁 | F9: =SUM(C9:E9) -> 0 | U9: =sum(G9:T9) -> 0
B10: 마명철 | F10: =SUM(C10:E10) -> 0 | U10: =sum(G10:T10) -> 0
B11: 일일누계 | C11: =SUM(C4:C10) -> 0 | D11: =SUM(D4:D10) -> 0 | E11: =SUM(E4:E10) -> 0 | F11: =SUM(F4:F10) -> 0 | G11: =SUM(G4:G10) -> 0 | H11: =SUM(H4:H10) -> 0 | I11: =SUM(I4:I10) -> 0 | J11: =SUM(J4:J10) -> 0 | ... T11: =SUM(T4:T10) -> 0 | U11: =sum(G11:T11) -> 0 | V11: 구분 | W11: 정신상담 | X11: 알콜상담 | Y11: 기타상담 | Z11: 소계 | AA11: 자의입원 | AB11: 응급입원 | AC11: 보호진단 | AD11: 시설입소(자활, 재활, 요양) | AE11: 시설입소(타복지시설) | AF11: 지원주택 | AG11: 주거지원 | AH11: 물품제공 | AI11: 기타(외래) | AJ11: 외래진료 | AK11: 병원방문 | AL11: 주거지방문 | AM11: 투약관리 | AN11: 기타(척도, 내방)
B12: 총누계 | C12: =C11+'2026년2월'!C282 -> 1103 | D12: =D11+'2026년2월'!D282 -> 406 | E12: =E11+'2026년2월'!E282 -> 5 | F12: =F11+'2026년2월'!F282 -> 1514 | G12: =G11+'2026년2월'!G282 -> 22 | H12: =H11+'2026년2월'!H282 -> 12 | I12: =I11+'2026년2월'!I282 -> 8 | J12: =J11+'2026년2월'!J282 -> 5 | ... U12: =U11+'2026년2월'!U282 -> 1623 | V12: 3월 1주차 | W12: =SUM('2026년2월'!C202:C206,'2026년2월'!C211:C215,'2026년2월'!C220:C224,'2026년2월'!C229:C233,'2026년2월'!C238:C242,'2026년2월'!C247:C251,C4:C8) -> 144 | X12: =SUM('2026년2월'!D202:D206,'2026년2월'!D211:D215,'2026년2월'!D220:D224,'2026년2월'!D229:D233,'2026년2월'!D238:D242,'2026년2월'!D247:D251,D4:D8) -> 45 | Y12: =SUM('2026년2월'!E202:E206,'2026년2월'!E211:E215,'2026년2월'!E220:E224,'2026년2월'!E229:E233,'2026년2월'!E238:E242,'2026년2월'!E247:E251,E4:E8) -> 0 | Z12: =SUM('2026년2월'!F202:F206,'2026년2월'!F211:F215,'2026년2월'!F220:F224,'2026년2월'!F229:F233,'2026년2월'!F238:F242,'2026년2월'!F247:F251,F4:F8) -> 189 | AA12: =SUM('2026년2월'!G202:G206,'2026년2월'!G211:G215,'2026년2월'!G220:G224,'2026년2월'!G229:G233,'2026년2월'!G238:G242,'2026년2월'!G247:G251,G4:G8) -> 3 | AB12: =SUM('2026년2월'!H202:H206,'2026년2월'!H211:H215,'2026년2월'!H220:H224,'2026년2월'!H229:H233,'2026년2월'!H238:H242,'2026년2월'!H247:H251,H4:H8) -> 0 | AC12: =SUM('2026년2월'!I202:I206,'2026년2월'!I211:I215,'2026년2월'!I220:I224,'2026년2월'!I229:I233,'2026년2월'!I238:I242,'2026년2월'!I247:I251,I4:I8) -> 0 | AD12: =SUM('2026년2월'!J202:J206,'2026년2월'!J211:J215,'2026년2월'!J220:J224,'2026년2월'!J229:J233,'2026년2월'!J238:J242,'2026년2월'!J247:J251,J4:J8) -> 2 | ... AN12: =SUM('2026년2월'!T202:T206,'2026년2월'!T211:T215,'2026년2월'!T220:T224,'2026년2월'!T229:T233,'2026년2월'!T238:T242,'2026년2월'!T247:T251,T4:T8) -> 30
A13: 46083 | B13: 조국일 | F13: =SUM(C13:E13) -> 0 | U13: =sum(G13:T13) -> 0
B14: 최리선 | F14: =SUM(C14:E14) -> 0 | U14: =sum(G14:T14) -> 0
B15: 안영호 | F15: =SUM(C15:E15) -> 0 | U15: =sum(G15:T15) -> 0
B16: 박상준 | F16: =SUM(C16:E16) -> 0 | U16: =sum(G16:T16) -> 0
B17: 김영민 | F17: =SUM(C17:E17) -> 0 | U17: =sum(G17:T17) -> 0
B18: 임종혁 | F18: =SUM(C18:E18) -> 0 | U18: =sum(G18:T18) -> 0
B19: 마명철 | F19: =SUM(C19:E19) -> 0 | U19: =sum(G19:T19) -> 0
B20: 일일누계 | C20: =SUM(C13:C19) -> 0 | D20: =SUM(D13:D19) -> 0 | E20: =SUM(E13:E19) -> 0 | F20: =SUM(F13:F19) -> 0 | G20: =SUM(G13:G19) -> 0 | H20: =SUM(H13:H19) -> 0 | I20: =SUM(I13:I19) -> 0 | J20: =SUM(J13:J19) -> 0 | ... T20: =SUM(T13:T19) -> 0 | U20: =sum(G20:T20) -> 0
B21: 총누계 | C21: =C12+C20 -> 1103 | D21: =D12+D20 -> 406 | E21: =E12+E20 -> 5 | F21: =F12+F20 -> 1514 | G21: =G12+G20 -> 22 | H21: =H12+H20 -> 12 | I21: =I12+I20 -> 8 | J21: =J12+J20 -> 5 | ... U21: =U12+U20 -> 1623
A22: 46084 | B22: 조국일 | F22: =SUM(C22:E22) -> 0 | U22: =sum(G22:T22) -> 0
B23: 최리선 | C23: 15 | D23: 3 | F23: =SUM(C23:E23) -> 18 | P23: 17 | T23: 2 | U23: =sum(G23:T23) -> 19
B24: 안영호 | D24: 4 | F24: =SUM(C24:E24) -> 4 | P24: 1 | T24: 3 | U24: =sum(G24:T24) -> 4
B25: 박상준 | F25: =SUM(C25:E25) -> 0 | U25: =sum(G25:T25) -> 0
B26: 김영민 | C26: 2 | F26: =SUM(C26:E26) -> 2 | P26: 1 | Q26: 1 | U26: =sum(G26:T26) -> 2
B27: 임종혁 | C27: 4 | D27: 1 | F27: =SUM(C27:E27) -> 5 | P27: 1 | T27: 5 | U27: =sum(G27:T27) -> 6
B28: 마명철 | C28: 0 | D28: 0 | F28: =SUM(C28:E28) -> 0 | U28: =sum(G28:T28) -> 0
B29: 일일누계 | C29: =SUM(C22:C28) -> 21 | D29: =SUM(D22:D28) -> 8 | E29: =SUM(E22:E28) -> 0 | F29: =SUM(F22:F28) -> 29 | G29: =SUM(G22:G28) -> 0 | H29: =SUM(H22:H28) -> 0 | I29: =SUM(I22:I28) -> 0 | J29: =SUM(J22:J28) -> 0 | ... T29: =SUM(T22:T28) -> 10 | U29: =sum(G29:T29) -> 31
B30: 총누계 | C30: =C21+C29 -> 1124 | D30: =D21+D29 -> 414 | E30: =E21+E29 -> 5 | F30: =F21+F29 -> 1543 | G30: =G21+G29 -> 22 | H30: =H21+H29 -> 12 | I30: =I21+I29 -> 8 | J30: =J21+J29 -> 5 | ... U30: =U21+U29 -> 1654
A31: 46085 | B31: 조국일 | C31: 3 | F31: =SUM(C31:E31) -> 3 | P31: 3 | U31: =sum(G31:T31) -> 3
B32: 최리선 | C32: 15 | D32: 2 | F32: =SUM(C32:E32) -> 17 | G32: 1 | P32: 16 | T32: 1 | U32: =sum(G32:T32) -> 18
B33: 안영호 | C33: 1 | D33: 2 | F33: =SUM(C33:E33) -> 3 | G33: 1 | T33: 2 | U33: =sum(G33:T33) -> 3
B34: 박상준 | C34: 2 | F34: =SUM(C34:E34) -> 2 | P34: 1 | T34: 1 | U34: =sum(G34:T34) -> 2
B35: 김영민 | C35: 1 | F35: =SUM(C35:E35) -> 1 | P35: 1 | U35: =sum(G35:T35) -> 1
B36: 임종혁 | C36: 1 | D36: 2 | F36: =SUM(C36:E36) -> 3 | G36: 1 | N36: 1 | P36: 2 | T36: 1 | U36: =sum(G36:T36) -> 5
B37: 마명철 | D37: 1 | F37: =SUM(C37:E37) -> 1 | G37: 1 | U37: =sum(G37:T37) -> 1
B38: 일일누계 | C38: =SUM(C31:C37) -> 23 | D38: =SUM(D31:D37) -> 7 | E38: =SUM(E31:E37) -> 0 | F38: =SUM(F31:F37) -> 30 | G38: =SUM(G31:G37) -> 4 | H38: =SUM(H31:H37) -> 0 | I38: =SUM(I31:I37) -> 0 | J38: =SUM(J31:J37) -> 0 | ... T38: =SUM(T31:T37) -> 5 | U38: =sum(G38:T38) -> 33
B39: 총누계 | C39: =C30+C38 -> 1147 | D39: =D30+D38 -> 421 | E39: =E30+E38 -> 5 | F39: =F30+F38 -> 1573 | G39: =G30+G38 -> 26 | H39: =H30+H38 -> 12 | I39: =I30+I38 -> 8 | J39: =J30+J38 -> 5 | ... U39: =U30+U38 -> 1687
A40: 46086 | B40: 조국일 | D40: 1 | F40: =SUM(C40:E40) -> 1 | O40: 1 | U40: =sum(G40:T40) -> 1
B41: 최리선 | C41: 2 | F41: =SUM(C41:E41) -> 2 | P41: 2 | T41: 1 | U41: =sum(G41:T41) -> 3
...

Sheet 법인월보고용
B2: 상담현황 | G2: 조치 | N2: 조치 후 사례관리 | R2: 기초상담 | S2: 합계
A3: 월별 | B3: 정신과 상담 | C3: 알코올 상담 | D3: 일반상담 | E3: 합계 | F3: 자의입원 | G3: 응급입원 | H3: 보호진단 | I3: 시설입소 | J3: 지원주택 | K3: 주거지원 | L3: 물품제공 | M3: 기타 | N3: 외래진료 | O3: 병원방문 | P3: 주거지방문 | Q3: 투약관리 | T3: 수급진행 | U3: 주민등록복원 | W3: 입원합
A4: 1월 | B4: ='2026년1월'!C293 -> 583 | C4: ='2026년1월'!D293 -> 229 | D4: ='2026년1월'!E293 -> 2 | E4: ='2026년1월'!F293 -> 814 | F4: ='2026년1월'!G293 -> 12 | G4: ='2026년1월'!H293 -> 8 | H4: ='2026년1월'!I293 -> 6 | I4: =SUM('2026년1월'!J293,'2026년1월'!K293) -> 1 | J4: ='2026년1월'!L293 -> 20 | K4: ='2026년1월'!M293 -> 17 | L4: ='2026년1월'!N293 -> 17 | M4: ='2026년1월'!O293 -> 12 | N4: ='2026년1월'!P293 -> 414 | O4: ='2026년1월'!Q293 -> 8 | P4: ='2026년1월'!R293 -> 164 | Q4: ='2026년1월'!S293 -> 6 | R4: ='2026년1월'!T293 -> 209 | S4: =SUM(F4:R4) -> 894 | W4: 1월
A5: 2월 | B5: ='2026년2월'!C293 -> 520 | C5: ='2026년2월'!D293 -> 177 | D5: ='2026년2월'!E293 -> 3 | E5: ='2026년2월'!F293 -> 700 | F5: ='2026년2월'!G293 -> 10 | G5: ='2026년2월'!H293 -> 4 | H5: ='2026년2월'!I293 -> 2 | I5: =SUM('2026년2월'!J293,'2026년2월'!K293) -> 4 | J5: ='2026년2월'!L293 -> 8 | K5: ='2026년2월'!M293 -> 24 | L5: ='2026년2월'!N293 -> 5 | M5: ='2026년2월'!O293 -> 11 | N5: ='2026년2월'!P293 -> 440 | O5: ='2026년2월'!Q293 -> 1 | P5: ='2026년2월'!R293 -> 62 | Q5: ='2026년2월'!S293 -> 3 | R5: ='2026년2월'!T293 -> 155 | S5: =SUM(F5:R5) -> 729 | W5: 2월
A6: 3월 | B6: ='2026년3월'!C293 -> #REF! | C6: ='2026년3월'!D293 -> #REF! | D6: ='2026년3월'!E293 -> #REF! | E6: ='2026년3월'!F293 -> #REF! | F6: ='2026년3월'!G293 -> #REF! | G6: ='2026년3월'!H293 -> #REF! | H6: ='2026년3월'!I293 -> #REF! | I6: =SUM('2026년3월'!J293,'2026년3월'!K293) -> #REF! | J6: ='2026년3월'!L293 -> #REF! | K6: ='2026년3월'!M293 -> #REF! | L6: ='2026년3월'!N293 -> #REF! | M6: ='2026년3월'!O293 -> #REF! | N6: ='2026년3월'!P293 -> #REF! | O6: ='2026년3월'!Q293 -> #REF! | P6: ='2026년3월'!R293 -> #REF! | Q6: ='2026년3월'!S293 -> #REF! | R6: ='2026년3월'!T293 -> #REF! | S6: =SUM(F6:R6) -> #REF! | W6: 3월
A7: 1분기 | B7: =SUM(B4:B6) -> #REF! | C7: =SUM(C4:C6) -> #REF! | D7: =SUM(D4:D6) -> #REF! | E7: =SUM(E4:E6) -> #REF! | F7: =SUM(F4:F6) -> #REF! | G7: =SUM(G4:G6) -> #REF! | H7: =SUM(H4:H6) -> #REF! | I7: =SUM(I4:I6) -> #REF! | ... S7: =SUM(S4:S6) -> #REF! | X7: 분기합
A8: 4월 | B8: ='2026년4월'!C$293 -> #REF! | C8: ='2026년4월'!D$293 -> #REF! | D8: ='2026년4월'!E$293 -> #REF! | E8: ='2026년4월'!F$293 -> #REF! | F8: ='2026년4월'!G$293 -> #REF! | G8: ='2026년4월'!H$293 -> #REF! | H8: ='2026년4월'!I$293 -> #REF! | I8: =SUM('2025년4월'!J293,'2025년6월'!K293) -> #REF! | J8: ='2026년4월'!L293 -> #REF! | K8: ='2026년4월'!M293 -> #REF! | L8: ='2026년4월'!N293 -> #REF! | M8: ='2026년4월'!O293 -> #REF! | N8: ='2026년4월'!P293 -> #REF! | O8: ='2026년4월'!Q293 -> #REF! | P8: ='2026년4월'!R293 -> #REF! | Q8: ='2026년4월'!S293 -> #REF! | R8: ='2026년4월'!T293 -> #REF! | S8: =SUM(F8:R8) -> #REF! | W8: 4월
A9: 5월 | B9: ='2026년5월'!C$293 -> #REF! | C9: ='2026년5월'!D$293 -> #REF! | D9: ='2026년5월'!E$293 -> #REF! | E9: ='2026년5월'!F$293 -> #REF! | F9: ='2026년5월'!G$293 -> #REF! | G9: ='2026년5월'!H$293 -> #REF! | H9: ='2026년5월'!I$293 -> #REF! | I9: =SUM('2025년5월'!J293,'2025년6월'!K293) -> #REF! | J9: ='2026년5월'!L293 -> #REF! | K9: ='2026년5월'!M293 -> #REF! | L9: ='2026년5월'!N293 -> #REF! | M9: ='2026년5월'!O293 -> #REF! | N9: ='2026년5월'!P293 -> #REF! | O9: ='2026년5월'!Q293 -> #REF! | P9: ='2026년5월'!R293 -> #REF! | Q9: ='2026년5월'!S293 -> #REF! | R9: ='2026년5월'!T293 -> #REF! | S9: =SUM(F9:R9) -> #REF! | W9: 5월
A10: 6월 | B10: ='2026년6월'!C$293 -> #REF! | C10: ='2026년6월'!D$293 -> #REF! | D10: ='2026년6월'!E$293 -> #REF! | E10: ='2026년6월'!F$293 -> #REF! | F10: ='2026년6월'!G$293 -> #REF! | G10: ='2026년6월'!H$293 -> #REF! | H10: ='2026년6월'!I$293 -> #REF! | I10: =SUM('2025년6월'!J293,'2025년6월'!K293) -> #REF! | J10: ='2026년6월'!L$293 -> #REF! | K10: ='2026년6월'!M$293 -> #REF! | L10: ='2026년6월'!N$293 -> #REF! | M10: ='2026년6월'!O$293 -> #REF! | N10: ='2026년6월'!P$293 -> #REF! | O10: ='2026년6월'!Q$293 -> #REF! | P10: ='2026년6월'!R$293 -> #REF! | Q10: ='2026년6월'!S$293 -> #REF! | R10: ='2026년6월'!T$293 -> #REF! | S10: =SUM(F10:R10) -> #REF! | W10: 6월
A11: 2분기 | B11: =SUM(B8:B10) -> #REF! | C11: =SUM(C8:C10) -> #REF! | D11: =SUM(D8:D10) -> #REF! | E11: =SUM(E8:E10) -> #REF! | F11: =SUM(F8:F10) -> #REF! | G11: =SUM(G8:G10) -> #REF! | H11: =SUM(H8:H10) -> #REF! | I11: =SUM(I8:I10) -> #REF! | ... S11: =SUM(S8:S10) -> #REF! | X11: 분기합
A12: 상반기 | B12: =SUM(B7+B11) -> #REF! | C12: =SUM(C7+C11) -> #REF! | D12: =SUM(D7+D11) -> #REF! | E12: =SUM(E7+E11) -> #REF! | F12: =SUM(F7+F11) -> #REF! | G12: =SUM(G7+G11) -> #REF! | H12: =SUM(H7+H11) -> #REF! | I12: =SUM(I7+I11) -> #REF! | ... S12: =SUM(S7+S11) -> #REF! | X12: 상반기
A13: 7월 | B13: ='2026년7월'!C$293 -> #REF! | C13: ='2026년7월'!D$293 -> #REF! | D13: ='2026년7월'!E$293 -> #REF! | E13: ='2026년7월'!F$293 -> #REF! | F13: ='2026년7월'!G$293 -> #REF! | G13: ='2026년7월'!H$293 -> #REF! | H13: ='2026년7월'!I$293 -> #REF! | I13: =SUM('2026년7월'!J$293,'2026년7월'!K$293) -> #REF! | J13: ='2026년7월'!L$293 -> #REF! | K13: ='2026년7월'!M$293 -> #REF! | L13: ='2026년7월'!N$293 -> #REF! | M13: ='2026년7월'!O$293 -> #REF! | N13: ='2026년7월'!P$293 -> #REF! | O13: ='2026년7월'!Q$293 -> #REF! | P13: ='2026년7월'!R$293 -> #REF! | Q13: ='2026년7월'!S$293 -> #REF! | R13: ='2026년7월'!T$293 -> #REF! | S13: =SUM(F13:R13) -> #REF! | W13: 7월
A14: 8월 | B14: ='2026년8월'!C$293 -> #REF! | C14: ='2026년8월'!D$293 -> #REF! | D14: ='2026년8월'!E$293 -> #REF! | E14: ='2026년8월'!F$293 -> #REF! | F14: ='2026년8월'!G$293 -> #REF! | G14: ='2026년8월'!H$293 -> #REF! | H14: ='2026년8월'!I$293 -> #REF! | I14: =SUM('2026년8월'!J$293,'2026년8월'!K$293) -> #REF! | J14: ='2026년8월'!L$293 -> #REF! | K14: ='2026년8월'!M$293 -> #REF! | L14: ='2026년8월'!N$293 -> #REF! | M14: ='2026년8월'!O$293 -> #REF! | N14: ='2026년8월'!P$293 -> #REF! | O14: ='2026년8월'!Q$293 -> #REF! | P14: ='2026년8월'!R$293 -> #REF! | Q14: ='2026년8월'!S$293 -> #REF! | R14: ='2026년8월'!T$293 -> #REF! | S14: =SUM(F14:R14) -> #REF! | W14: 8월
A15: 9월 | B15: ='2026년9월'!C$293 -> #REF! | C15: ='2026년9월'!D$293 -> #REF! | D15: ='2026년9월'!E$293 -> #REF! | E15: ='2026년9월'!F$293 -> #REF! | F15: ='2026년9월'!G$293 -> #REF! | G15: ='2026년9월'!H$293 -> #REF! | H15: ='2026년9월'!I$293 -> #REF! | I15: =SUM('2026년9월'!J$293,'2026년9월'!K$293) -> #REF! | J15: ='2026년9월'!K$293 -> #REF! | K15: ='2026년9월'!L$293 -> #REF! | L15: ='2026년9월'!M$293 -> #REF! | M15: ='2026년9월'!N$293 -> #REF! | N15: ='2026년9월'!O$293 -> #REF! | O15: ='2026년9월'!P$293 -> #REF! | P15: ='2026년9월'!Q$293 -> #REF! | Q15: ='2026년9월'!R$293 -> #REF! | R15: ='2026년9월'!S$293 -> #REF! | S15: =SUM(F15:R15) -> #REF! | W15: 9월
A16: 3분기 | B16: =sum(B13:B15) -> #REF! | C16: =sum(C13:C15) -> #REF! | D16: =sum(D13:D15) -> #REF! | E16: =sum(E13:E15) -> #REF! | F16: =sum(F13:F15) -> #REF! | G16: =sum(G13:G15) -> #REF! | H16: =sum(H13:H15) -> #REF! | I16: =sum(I13:I15) -> #REF! | ... S16: =sum(S13:S15) -> #REF! | X16: 분기합
A17: 10월 | B17: ='2026년10월'!C$293 -> #REF! | C17: ='2026년10월'!D$293 -> #REF! | D17: ='2026년10월'!E$293 -> #REF! | E17: ='2026년10월'!F$293 -> #REF! | F17: ='2026년10월'!G$293 -> #REF! | G17: ='2026년10월'!H$293 -> #REF! | H17: ='2026년10월'!I$293 -> #REF! | I17: =SUM('2026년10월'!J293,'2026년10월'!K293) -> #REF! | J17: ='2026년10월'!L$293 -> #REF! | K17: ='2026년10월'!M$293 -> #REF! | L17: ='2026년10월'!N$293 -> #REF! | M17: ='2026년10월'!O$293 -> #REF! | N17: ='2026년10월'!P$293 -> #REF! | O17: ='2026년10월'!Q$293 -> #REF! | P17: ='2026년10월'!R$293 -> #REF! | Q17: ='2026년10월'!S$293 -> #REF! | R17: ='2026년10월'!T$293 -> #REF! | S17: =SUM(F17:R17) -> #REF! | W17: 10월
A18: 11월 | B18: ='2026년11월'!C$293 -> #REF! | C18: ='2026년11월'!D$293 -> #REF! | D18: ='2026년11월'!E$293 -> #REF! | E18: ='2026년11월'!F$293 -> #REF! | F18: ='2026년11월'!G$293 -> #REF! | G18: ='2026년11월'!H$293 -> #REF! | H18: ='2026년11월'!I$293 -> #REF! | I18: =SUM('2026년11월'!J293,'2026년11월'!K293) -> #REF! | J18: ='2026년11월'!L$293 -> #REF! | K18: ='2026년11월'!M$293 -> #REF! | L18: ='2026년11월'!N$293 -> #REF! | M18: ='2026년11월'!O$293 -> #REF! | N18: ='2026년11월'!P$293 -> #REF! | O18: ='2026년11월'!Q$293 -> #REF! | P18: ='2026년11월'!R$293 -> #REF! | Q18: ='2026년11월'!S$293 -> #REF! | R18: ='2026년11월'!T$293 -> #REF! | S18: =SUM(F18:R18) -> #REF! | W18: 11월
A19: 12월 | B19: ='2026년12월'!C$293 -> #REF! | C19: ='2026년12월'!D$293 -> #REF! | D19: ='2026년12월'!E$293 -> #REF! | E19: ='2026년12월'!F$293 -> #REF! | F19: ='2026년12월'!G$293 -> #REF! | G19: ='2026년12월'!H$293 -> #REF! | H19: ='2026년12월'!I$293 -> #REF! | I19: =SUM('2026년12월'!J293,'2026년12월'!K293) -> #REF! | J19: ='2026년12월'!L$293 -> #REF! | K19: ='2026년12월'!M$293 -> #REF! | L19: ='2026년12월'!N$293 -> #REF! | M19: ='2026년12월'!O$293 -> #REF! | N19: ='2026년12월'!P$293 -> #REF! | O19: ='2026년12월'!Q$293 -> #REF! | P19: ='2026년12월'!R$293 -> #REF! | Q19: ='2026년12월'!S$293 -> #REF! | R19: ='2026년12월'!T$293 -> #REF! | S19: =SUM(F19:R19) -> #REF! | W19: 12월
A20: 4분기 | B20: =SUM(B17:B19) -> #REF! | C20: =SUM(C17:C19) -> #REF! | D20: =SUM(D17:D19) -> #REF! | E20: =SUM(E17:E19) -> #REF! | F20: =SUM(F17:F19) -> #REF! | G20: =SUM(G17:G19) -> #REF! | H20: =SUM(H17:H19) -> #REF! | I20: =SUM(I17:I19) -> #REF! | ... S20: =SUM(S17:S19) -> #REF! | X20: 분기합
A21: 하반기 | B21: =SUM(B16+B20) -> #REF! | C21: =SUM(C16+C20) -> #REF! | D21: =SUM(D16+D20) -> #REF! | E21: =SUM(E16+E20) -> #REF! | F21: =SUM(F16+F20) -> #REF! | G21: =SUM(G16+G20) -> #REF! | H21: =SUM(H16+H20) -> #REF! | I21: =SUM(I16+I20) -> #REF! | ... S21: =SUM(S16+S20) -> #REF! | X21: 하반기
A22: 총합계 | B22: =SUM(B12+B21) -> #REF! | C22: =SUM(C12+C21) -> #REF! | D22: =SUM(D12+D21) -> #REF! | E22: =SUM(E12+E21) -> #REF! | F22: =SUM(F12+F21) -> #REF! | G22: =SUM(G12+G21) -> #REF! | H22: =SUM(H12+H21) -> #REF! | I22: =SUM(I12+I21) -> #REF! | ... U22: =SUM(U12+U21) -> 0 | X22: 년합계

Sheet 분기보고용
A1: 정신건강팀 활동실적 (2026년)
A3: 1. 상담
A4: 구분 | B4: 분기 | C4: 계 | D4: 정신과 상담 | E4: 알콜상담 | F4: 기타상담 | G4: 비 고
A5: 계 | C5: =sum(D5:F5) -> #REF! | D5: =sum(D6:D9) -> #REF! | E5: =sum(E6:E9) -> #REF! | F5: =sum(F6:F9) -> #REF!
A6: 다시서기 | B6: 1분기 | C6: =sum(D6:F6) -> #REF! | D6: ='법인월보고용'!B7 -> #REF! | E6: ='법인월보고용'!C7 -> #REF! | F6: ='법인월보고용'!D7 -> #REF!
A7: 다시서기 | B7: 2분기 | C7: =sum(D7:F7) -> #REF! | D7: ='법인월보고용'!B11 -> #REF! | E7: ='법인월보고용'!C11 -> #REF! | F7: ='법인월보고용'!D11 -> #REF!
A8: 다시서기 | B8: 3분기 | C8: =sum(D8:F8) -> #REF! | D8: ='법인월보고용'!B16 -> #REF! | E8: ='법인월보고용'!C16 -> #REF! | F8: ='법인월보고용'!D16 -> #REF!
A9: 다시서기 | B9: 4분기 | C9: =sum(D9:F9) -> #REF! | D9: ='법인월보고용'!B20 -> #REF! | E9: ='법인월보고용'!C20 -> #REF! | F9: ='법인월보고용'!D20 -> #REF!
A10: * 연상담건수 : 건
A13: 2. 조치
A14: 구분 | B14: 분기 | C14: 계 | D14: 병원입원 | G14: 시설입소 | J14: 주거지원 | K14: 기타 | S14: 자의입원 | T14: 자활시설 | U14: 센터거리상담반
D15: 소계 | E15: 자의 | F15: 응급/행정 | G15: 소계 | H15: 재활/ | I15: 일시 | K15: (귀가 등) | S15: 응급입원 | T15: 재활시설 | U15: 위기대응콜
E16: 입원 | F16: 입원 | H16: 자활/요양 | I16: 보호 | S16: 보호진단 | T16: 요양시설 | U16: 구청 등 유관기관
A17: 계 | C17: =SUM(C18:C21) -> #REF! | D17: =sum(E17:F17) -> 54 | E17: =SUM(E18:E21) -> 29 | F17: =SUM(F18:F21) -> 25 | G17: =SUM(H17:I17) -> 4 | H17: =SUM(H18:H21) -> 4 | I17: =SUM(I18:I21) -> 0 | J17: =SUM(J18:J21) -> #REF! | K17: =SUM(K18:K21) -> #REF! | S17: 보호입원 | T17: 일시보호시설 | U17: 노숙인방문
A18: 다시서기 | B18: 1분기 | C18: =SUM(D18,G18,J18,K18) -> #REF! | D18: =sum(E18:F18) -> 54 | E18: =countifs('입원현황'!$B:$B,">=1",'입원현황'!$B:$B,"<=3",'입원현황'!$G:$G,"자의입원") -> 29 | F18: =SUMPRODUCT(countifs('입원현황'!$B:$B,">=1",'입원현황'!$B:$B,"<=3",'입원현황'!$G:$G,$S$15:$S$18)) -> 25 | G18: =SUM(H18:H19) -> 4 | H18: =SUMPRODUCT(COUNTIFS('시설입소현황'!B:B,">=1",'시설입소현황'!B:B,"<=3",'시설입소현황'!J:J,$T$14:$T$16)) -> 4 | I18: =COUNTIFS('시설입소현황'!C:C,">=1",'시설입소현황'!C:C,"<=3",'시설입소현황'!K:K,T17) -> 0 | J18: ='법인월보고용'!K7 -> #REF! | K18: ='법인월보고용'!M7 -> #REF! | S18: 동의입원 | T18: 지원주택 | U18: 노숙인시설개입요청
A19: 다시서기 | B19: 2분기 | C19: =SUM(D19,G19,J19,K19) -> #REF! | D19: =sum(E19:F19) -> 0 | E19: =countifs('입원현황'!B:B,">=4",'입원현황'!B:B,"<=6",'입원현황'!G:G,"자의입원") -> 0 | F19: =SUMPRODUCT(countifs('입원현황'!$B:$B,">=4",'입원현황'!$B:$B,"<=6",'입원현황'!$G:$G,$S$15:$S$18)) -> 0 | G19: =SUM(H19:H20) -> 0 | H19: =SUMPRODUCT(COUNTIFS('시설입소현황'!B:B,">=4",'시설입소현황'!B:B,"<=6",'시설입소현황'!J:J,$T$14:$T$16)) -> 0 | I19: =COUNTIFS('시설입소현황'!C:C,">=4",'시설입소현황'!C:C,"<=6",'시설입소현황'!K:K,T17) -> 0 | J19: ='법인월보고용'!K11 -> #REF! | K19: ='법인월보고용'!M11 -> #REF! | T19: 기타
A20: 다시서기 | B20: 3분기 | C20: =SUM(D20,G20,J20,K20) -> #REF! | D20: =sum(E20:F20) -> 0 | E20: =countifs('입원현황'!B:B,">=7",'입원현황'!B:B,"<=9",'입원현황'!G:G,"자의입원") -> 0 | F20: =SUMPRODUCT(countifs('입원현황'!$B:$B,">=7",'입원현황'!$B:$B,"<=9",'입원현황'!$G:$G,$S$15:$S$18)) -> 0 | G20: =SUM(H20:H21) -> 0 | H20: =SUMPRODUCT(COUNTIFS('시설입소현황'!B:B,">=7",'시설입소현황'!B:B,"<=9",'시설입소현황'!J:J,$T$14:$T$16)) -> 0 | I20: =COUNTIFS('시설입소현황'!C:C,">=7",'시설입소현황'!C:C,"<=9",'시설입소현황'!K:K,T17) -> 0 | J20: ='법인월보고용'!K16 -> #REF! | K20: ='법인월보고용'!M16 -> #REF!
A21: 다시서기 | B21: 4분기 | C21: =SUM(D21,G21,J21,K21) -> #REF! | D21: =sum(E21:F21) -> 0 | E21: =countifs('입원현황'!B:B,">=10",'입원현황'!B:B,"<=12",'입원현황'!G:G,"자의입원") -> 0 | F21: =SUMPRODUCT(countifs('입원현황'!$B:$B,">=10",'입원현황'!$B:$B,"<=12",'입원현황'!$G:$G,$S$15:$S$18)) -> 0 | G21: =SUM(H21:H22) -> 0 | H21: =SUMPRODUCT(COUNTIFS('시설입소현황'!B:B,">=10",'시설입소현황'!B:B,"<=12",'시설입소현황'!J:J,$T$14:$T$16)) -> 0 | I21: =COUNTIFS('시설입소현황'!C:C,">=10",'시설입소현황'!C:C,"<=12",'시설입소현황'!K:K,T17) -> 0 | J21: ='법인월보고용'!K20 -> #REF! | K21: ='법인월보고용'!M20 -> #REF!
S22: 1 | T22: 4 | U22: 7 | V22: 10
A23: 3. 연계경로 | S23: 2 | T23: 5 | U23: 8 | V23: 11
A24: 구분 | B24: 분기 | C24: 계 | D24: 센터 거리 | E24: 위기 | F24: 구청 등 | G24: 노숙인 | H24: 노숙인시설 | I24: 직접발굴 | S24: 3 | T24: 6 | U24: 9 | V24: 12
D25: 상담반 | E25: 대응콜 | F25: 유관기관 | G25: 방문 | H25: 개입요청 | I25: (아웃리치)
A26: 계 | D26: =SUM(D27:D30) -> 0 | E26: =SUM(E27:E30) -> 0 | F26: =SUM(F27:F30) -> 0 | G26: =SUM(G27:G30) -> 0 | H26: =SUM(H27:H30) -> 0 | I26: =SUM(I27:I30) -> 0
A27: 다시서기 | B27: 1분기 | C27: =SUM(D27:I27) -> 0 | I27: 0
A28: 다시서기 | B28: 2분기 | C28: =SUM(D28:I28) -> 0 | I28: 0
A29: 다시서기 | B29: 3분기 | C29: =SUM(D29:I29) -> 0 | I29: 0
A30: 다시서기 | B30: 4분기 | C30: =SUM(D30:I30) -> 0
S31: 귀가 | T31: 연락두절
A32: 4. 병원입원 후 사례관리 | S32: 시설연계 | T32: 사망
A33: 구분 | B33: 분기 | C33: 입원조치 인원 | D33: 입원치료중 | E33: 퇴원 후 연계 서비스 | M33: 입원 중 사례관리 | S33: 주거지원 | T33: 체포 및 수감
E34: 소계 | F34: 귀가 | G34: 시설연계 | H34: 주거지원 | I34: 일자리지원 | J34: 재입원 | K34: 연락두절 등기타 | L34: 재노숙 | M34: 병원방문 | N34: 주민등록 | O34: 수급획득 | S34: 일자리지원 | T34: 귀환
S35: 재입원 | T35: 전원
A36: 계 | C36: =SUM(C37:C40) -> 54 | D36: =SUM(D37:D40) -> 44 | E36: =SUM(E37:E40) -> 7 | F36: =SUM(F37:F40) -> 0 | G36: =SUM(G37:G40) -> 0 | H36: =SUM(H37:H40) -> 0 | I36: =SUM(I37:I40) -> 0 | J36: =SUM(J37:J40) -> 3 | ... O36: =SUM(O37:O40) -> 2 | S36: 재노숙 | T36: 기타
A37: 다시서기 | B37: 1분기 | C37: =sum(COUNTIF('입원현황'!$B:$B,1),COUNTIF('입원현황'!$B:$B,2),COUNTIF('입원현황'!$B:$B,3)) -> 54 | D37: =countifs('입원현황'!$B:$B,">=1",'입원현황'!$B:$B,"<=3",'입원현황'!$M:$M,"입원중") -> 44 | E37: =SUM(F37:L37) -> 7 | F37: =countifs('입원현황'!$B:$B,">=1",'입원현황'!$B:$B,"<=3",'입원현황'!$P:$P,S$30) -> 0 | G37: =countifs('입원현황'!$B:$B,">=1",'입원현황'!$B:$B,"<=3",'입원현황'!$P:$P,S$32) -> 0 | H37: =countifs('입원현황'!$B:$B,">=1",'입원현황'!$B:$B,"<=3",'입원현황'!$P:$P,S$33) -> 0 | I37: =countifs('입원현황'!$B:$B,">=1",'입원현황'!$B:$B,"<=3",'입원현황'!$P:$P,S$34) -> 0 | J37: =countifs('입원현황'!$B:$B,">=1",'입원현황'!$B:$B,"<=3",'입원현황'!$P:$P,S$35) -> 3 | K37: =SUMPRODUCT(countifs('입원현황'!$B:$B,">=1",'입원현황'!$B:$B,"<=3",'입원현황'!$P:$P,$T$31:$T$36)) -> 4 | L37: =countifs('입원현황'!$B:$B,">=1",'입원현황'!$B:$B,"<=3",'입원현황'!$P:$P,Y$30) -> 0 | M37: ='법인월보고용'!O7 -> #REF! | N37: =SUM('조치후 사례관리'!R19:R21,'조치후 사례관리'!T19:T21) -> 2 | O37: =SUM('조치후 사례관리'!V19:V21) -> 2
A38: 다시서기 | B38: 2분기 | C38: =sum(COUNTIF('입원현황'!$B:$B,4),COUNTIF('입원현황'!$B:$B,5),COUNTIF('입원현황'!$B:$B,6)) -> 0 | D38: =countifs('입원현황'!$B:$B,">=4",'입원현황'!$B:$B,"<=6",'입원현황'!$M:$M,"입원중") -> 0 | E38: =SUM(F38:L38) -> 0 | F38: =countifs('입원현황'!$B:$B,">=4",'입원현황'!$B:$B,"<=6",'입원현황'!$P:$P,S$30) -> 0 | G38: =countifs('입원현황'!$B:$B,">=4",'입원현황'!$B:$B,"<=6",'입원현황'!$P:$P,S$32) -> 0 | H38: =countifs('입원현황'!$B:$B,">=4",'입원현황'!$B:$B,"<=6",'입원현황'!$P:$P,S$33) -> 0 | I38: =countifs('입원현황'!$B:$B,">=4",'입원현황'!$B:$B,"<=6",'입원현황'!$P:$P,S$34) -> 0 | J38: =countifs('입원현황'!$B:$B,">=4",'입원현황'!$B:$B,"<=6",'입원현황'!$P:$P,S$35) -> 0 | K38: =SUMPRODUCT(countifs('입원현황'!$B:$B,">=4",'입원현황'!$B:$B,"<=6",'입원현황'!$P:$P,$T$31:$T$36)) -> 0 | L38: =countifs('입원현황'!$B:$B,">=4",'입원현황'!$B:$B,"<=6",'입원현황'!$P:$P,Y$30) -> 0 | M38: ='법인월보고용'!O11 -> #REF! | N38: =SUM('조치후 사례관리'!R22:R24,'조치후 사례관리'!T22:T24) -> 0 | O38: =SUM('조치후 사례관리'!V22:V24) -> 0
A39: 다시서기 | B39: 3분기 | C39: =sum(COUNTIF('입원현황'!$B:$B,7),COUNTIF('입원현황'!$B:$B,8),COUNTIF('입원현황'!$B:$B,9)) -> 0 | D39: =countifs('입원현황'!$B:$B,">=7",'입원현황'!$B:$B,"<=9",'입원현황'!$M:$M,"입원중") -> 0 | E39: =SUM(F39:L39) -> 0 | F39: =countifs('입원현황'!$B:$B,">=7",'입원현황'!$B:$B,"<=9",'입원현황'!$P:$P,S$30) -> 0 | G39: =countifs('입원현황'!$B:$B,">=7",'입원현황'!$B:$B,"<=9",'입원현황'!$P:$P,S$32) -> 0 | H39: =countifs('입원현황'!$B:$B,">=7",'입원현황'!$B:$B,"<=9",'입원현황'!$P:$P,S$33) -> 0 | I39: =countifs('입원현황'!$B:$B,">=7",'입원현황'!$B:$B,"<=9",'입원현황'!$P:$P,S$34) -> 0 | J39: =countifs('입원현황'!$B:$B,">=7",'입원현황'!$B:$B,"<=9",'입원현황'!$P:$P,S$35) -> 0 | K39: =SUMPRODUCT(countifs('입원현황'!$B:$B,">=7",'입원현황'!$B:$B,"<=9",'입원현황'!$P:$P,$T$31:$T$36)) -> 0 | L39: =countifs('입원현황'!$B:$B,">=7",'입원현황'!$B:$B,"<=9",'입원현황'!$P:$P,Y$30) -> 0 | M39: ='법인월보고용'!O16 -> #REF! | N39: =SUM('조치후 사례관리'!R25:R27,'조치후 사례관리'!T25:T27) -> 0 | O39: =SUM('조치후 사례관리'!V25:V27) -> 0
A40: 다시서기 | B40: 4분기 | C40: =SUMPRODUCT(countifs('입원현황'!$B:$B,">=10",'입원현황'!$B:$B,"<=12",'입원현황'!$G:$G,$S$14:$S$18)) -> 0 | D40: =countifs('입원현황'!$B:$B,">=10",'입원현황'!$B:$B,"<=12",'입원현황'!$M:$M,"입원중") -> 0 | E40: =SUM(F40:L40) -> 0 | F40: =countifs('입원현황'!$B:$B,">=10",'입원현황'!$B:$B,"<=12",'입원현황'!$P:$P,S$30) -> 0 | G40: =countifs('입원현황'!$B:$B,">=10",'입원현황'!$B:$B,"<=12",'입원현황'!$P:$P,S$32) -> 0 | H40: =countifs('입원현황'!$B:$B,">=10",'입원현황'!$B:$B,"<=12",'입원현황'!$P:$P,S$33) -> 0 | I40: =countifs('입원현황'!$B:$B,">=10",'입원현황'!$B:$B,"<=12",'입원현황'!$P:$P,S$34) -> 0 | J40: =countifs('입원현황'!$B:$B,">=10",'입원현황'!$B:$B,"<=12",'입원현황'!$P:$P,S$35) -> 0 | K40: =SUMPRODUCT(countifs('입원현황'!$B:$B,">=10",'입원현황'!$B:$B,"<=12",'입원현황'!$P:$P,$T$31:$T$36)) -> 0 | L40: =countifs('입원현황'!$B:$B,">=10",'입원현황'!$B:$B,"<=12",'입원현황'!$P:$P,Y$30) -> 0 | M40: ='법인월보고용'!O20 -> #REF! | N40: =SUM('조치후 사례관리'!R28:R30,'조치후 사례관리'!T28:T30) -> 0 | O40: =SUM('조치후 사례관리'!V28:V30) -> 0
S41: 귀가
A42: 5. 시설입소 후 사례관리 | S42: 타시설전원
A43: 구분 | B43: 분기 | C43: 입소조치인원 | D43: 입소중 | E43: 퇴소 후 연계 서비스 | S43: 병원입원
...

Sheet 전체입원현황(15년부터)
A1: 연번 | B1: 월 | C1: 입원날짜 | D1: 성별 | E1: 대상자명 | F1: 생년월일 | G1: 입원형태 | H1: 질환명 | I1: 병원명 | J1: 담당자 | K1: 사례관리담당자 | L1: 진단명 | M1: 입원여부 | N1: 입원기간 | O1: 퇴원일 | P1: 퇴원 후 연계 | Q1: 비고
A2: 85 | C2: 45244 | D2: 남 | E2: 조문종 | F2: 711005-1 | G2: 자의입원 | H2: 정신 | I2: 해상병원 | L2: 조현병 | M2: 퇴원 | N2: =O2-C2 -> 50 | O2: 45294 | P2: 귀가
A3: 105 | B3: =MONTH(C3) -> 1 | C3: 45296 | D3: 남 | E3: 송원배 | F3: 660922-1 | G3: 자의입원 | H3: 알코올 | I3: 라엘정신건강의학과 | J3: 임종혁 | L3: 알코올의존 | M3: 퇴원 | N3: =O3-C3 -> 3 | O3: 45299 | P3: 재입원 | Q3: 서북병원 내과 입원
A4: 69 | C4: 45113 | D4: 남 | E4: 김동수 | F4: 610511-1 | G4: 자의입원 | H4: 알코올 | I4: 해상병원 | L4: 알코올의존 | M4: 퇴원 | N4: =O4-C4 -> 187 | O4: 45300 | P4: 연락두절
A5: 95 | B5: =MONTH(C5) -> 12 | C5: 45264 | D5: 남 | E5: 이기삼 | F5: 660915-1 | G5: 자의입원 | H5: 정신 | I5: 라엘정신건강의학과 | L5: 조울증 | M5: 퇴원 | N5: =O5-C5 -> 36 | O5: 45300 | P5: 연락두절
A6: 104 | B6: =MONTH(C6) -> 1 | C6: 45295 | D6: 남 | E6: 오동진 | F6: 970318-1 | G6: 자의입원 | H6: 정신 | I6: 라엘정신건강의학과 | J6: 조국일 | K6: 조국일 | L6: 우울증, 자살사고 | M6: 퇴원 | N6: =O6-C6 -> 8 | O6: 45303 | P6: 시설연계 | Q6: 비전트레이닝센터
A7: 111 | B7: =MONTH(C7) -> 1 | C7: 45303 | D7: 남 | E7: 김덕기 | F7: 801104-1 | G7: 자의입원 | H7: 알코올 | I7: 김포다은병원 | J7: 임종혁 | L7: 알코올의존 | M7: 퇴원 | N7: =O7-C7 -> 7 | O7: 45310 | P7: 재노숙
A8: 112 | B8: =MONTH(C8) -> 1 | C8: 45305 | D8: 남 | E8: 정재창 | F8: 670807-1 | G8: 자의입원 | H8: 알코올 | I8: 백암병원 | J8: 김영민 | L8: 알코올의존 | M8: 퇴원 | N8: =O8-C8 -> 5 | O8: 45310 | P8: 재노숙
A9: 118 | B9: =MONTH(C9) -> 1 | C9: 45310 | D9: 여 | E9: 김세은 | F9: 970502-2 | G9: 응급입원 | H9: 정신 | I9: 김포다은병원 | J9: 임종혁 | L9: 조울증, 자살사고 | M9: 퇴원 | N9: =O9-C9 -> 3 | O9: 45313 | P9: 연락두절
A10: 102 | C10: 45289 | D10: 남 | E10: 송영석 | F10: 791122-1 | G10: 보호진단 | H10: 정신 | I10: 해상병원 | L10: 조현병 | M10: 퇴원 | N10: =O10-C10 -> 25 | O10: 45314 | P10: 전원 | Q10: 화정병원
A11: 83 | B11: =MONTH(C11) -> 10 | C11: 45228 | D11: 남 | E11: 방대수 | F11: 601209-1 | I11: 김포다은병원 | M11: 퇴원 | N11: =O11-C11 -> 94 | O11: 45322 | P11: 연락두절
A12: 128 | C12: 45324 | D12: 남 | E12: 김남윤 | F12: 951127-1 | G12: 응급입원 | H12: 정신 | I12: 라엘마음병원 | J12: 임종혁 | L12: 우울, 자살사고 | M12: 퇴원 | N12: =O12-C12 -> 4 | O12: 45328 | P12: 시설연계
A13: 93 | B13: =MONTH(C13) -> 11 | C13: 45259 | D13: 남 | E13: 황승민 | F13: 811208-1 | I13: 김포다은병원 | M13: 퇴원 | N13: =O13-C13 -> 72 | O13: 45331 | P13: 연락두절
A14: 84 | C14: 45240 | D14: 남 | E14: 이동식 | F14: 740317-1 | G14: 자의입원 | H14: 알코올 | I14: 해상병원 | L14: 알코올의존 | M14: 퇴원 | N14: =O14-C14 -> 96 | O14: 45336 | P14: 귀가
A15: 130 | C15: 45327 | D15: 남 | E15: 오동진 | F15: 970318-1 | G15: 자의입원 | H15: 정신 | I15: 해상병원 | J15: 조국일 | L15: 우울증 | M15: 퇴원 | N15: =O15-C15 -> 15 | O15: 45342 | P15: 시설연계 | Q15: 비전트레이닝센터 입소
A16: 136 | B16: =MONTH(C16) -> 2 | C16: 45333 | D16: 남 | E16: 김신흥 | F16: 680811-1 | G16: 자의입원 | H16: 정신 | I16: 김포다은병원 | J16: 김영민 | L16: 상세불명의 충동, 자살사고 | M16: 퇴원 | N16: =O16-C16 -> 9 | O16: 45342 | P16: 귀가
A17: 81 | B17: =MONTH(C17) -> 9 | C17: 45196 | D17: 여 | E17: 안나영 | F17: 730815-2 | I17: 김포다은병원 | M17: 퇴원 | N17: =O17-C17 -> 149 | O17: 45345 | P17: 연락두절
A18: 119 | C18: 45314 | D18: 남 | E18: 김옥동 | F18: 640329-1 | G18: 자의입원 | H18: 알코올 | I18: 축령정신병원 | J18: 조국일 | L18: 알코올의존 | M18: 퇴원 | N18: =O18-C18 -> 31 | O18: 45345 | P18: 연락두절
A19: 90 | C19: 45254 | D19: 남 | E19: 김평열 | F19: 690909-1 | G19: 자의입원 | H19: 알코올 | I19: 라엘마음병원 | L19: 알코올의존 | M19: 퇴원 | N19: =O19-C19 -> 94 | O19: 45348 | P19: 재노숙
A20: 91 | C20: 45254 | D20: 남 | E20: 박준용 | F20: 711027-1 | G20: 자의입원 | H20: 알코올 | I20: 라엘마음병원 | L20: 알코올의존 | M20: 퇴원 | N20: =O20-C20 -> 94 | O20: 45348 | P20: 재노숙
A21: 106 | B21: =MONTH(C21) -> 1 | C21: 45296 | D21: 남 | E21: 박성훈 | F21: 630816-1 | G21: 자의입원 | H21: 정신 | I21: 도은병원 | J21: 최리선 | L21: 조현병 | M21: 퇴원 | N21: =O21-C21 -> 53 | O21: 45349 | P21: 재입원
A22: 139 | B22: =MONTH(C22) -> 2 | C22: 45336 | D22: 남 | E22: 신현우 | F22: 641118-1 | G22: 보호진단 | H22: 알코올 | I22: 도은병원 | J22: 임종혁 | L22: 알코올의존, 우울, 자살사고 | M22: 퇴원 | N22: =O22-C22 -> 14 | O22: 45350 | P22: 귀가 | Q22: 귀가
A23: 122 | C23: 45317 | D23: 남 | E23: 이진구 | F23: 680224-1 | G23: 자의입원 | H23: 정신 | I23: 축령정신병원 | J23: 임종혁 | L23: 조현병 | M23: 퇴원 | N23: =O23-C23 -> 34 | O23: 45351 | P23: 시설연계 | Q23: 비전트레이닝센터 입소
A24: 137 | B24: =MONTH(C24) -> 2 | C24: 45335 | D24: 남 | E24: 김형순 | F24: 670922-1 | G24: 자의입원 | H24: 정신 | I24: 라엘정신건강의학과 | J24: 최리선 | L24: 우울증, 알코올의존 | M24: 퇴원 | N24: =O24-C24 -> 20 | O24: 45355 | P24: 귀가
A25: 109 | C25: 45300 | D25: 남 | E25: 박제석 | F25: 680828-1 | G25: 자의입원 | H25: 알코올 | I25: 해상병원 | J25: 임종혁 | L25: 알코올의존 | M25: 퇴원 | N25: =O25-C25 -> 71 | O25: 45371 | P25: 주거지원
A26: 132 | C26: 45329 | D26: 남 | E26: 김승준 | F26: 770216-1 | G26: 자의입원 | H26: 알코올 | I26: 축령정신병원 | J26: 임종혁 | L26: 알코올의존, 우울 | M26: 퇴원 | N26: =O26-C26 -> 42 | O26: 45371 | P26: 재노숙
A27: 149 | B27: =MONTH(C27) -> 2 | C27: 45351 | D27: 남 | E27: 이영국 | F27: 900220-1 | G27: 자의입원 | H27: 정신 | I27: 도은병원 | J27: 임종혁 | L27: 지적장애, 충동장애 | M27: 퇴원 | N27: =O27-C27 -> 20 | O27: 45371 | P27: 귀가
A28: 143 | B28: =MONTH(C28) -> 2 | C28: 45343 | D28: 남 | E28: 김창현 | F28: 660125-1 | G28: 자의입원 | H28: 정신 | I28: 도은병원 | J28: 최리선 | L28: 양극성정동장애 | M28: 퇴원 | N28: =O28-C28 -> 34 | O28: 45377 | P28: 주거지원
A29: 107 | B29: =MONTH(C29) -> 1 | C29: 45296 | D29: 남 | E29: 김경재 | F29: 470517-1 | G29: 보호진단 | H29: 정신 | I29: 도은병원 | J29: 임종혁 | L29: 치매, 조현병 | M29: 퇴원 | N29: =O29-C29 -> 88 | O29: 45384 | P29: 주거지원
A30: 162 | B30: =MONTH(C30) -> 3 | C30: 45371 | D30: 남 | E30: 황승민 | F30: 811208-1 | G30: 자의입원 | H30: 알코올 | I30: 김포다은병원 | J30: 임종혁 | L30: 알코올의존 | M30: 퇴원 | N30: =O30-C30 -> 13 | O30: 45384 | P30: 재입원
A31: 133 | C31: 45330 | D31: 남 | E31: 이완수 | F31: 720120-1 | G31: 자의입원 | H31: 알코올 | I31: 해상병원 | J31: 임종혁 | L31: 알코올의존 | M31: 퇴원 | N31: =O31-C31 -> 55 | O31: 45385 | P31: 귀가 | Q31: 지인집
A32: 108 | C32: 45299 | D32: 남 | E32: 김충돈 | F32: 700604-1 | G32: 보호진단 | H32: 정신 | I32: 축령정신병원 | J32: 임종혁 | L32: 조현정동장애 | M32: 퇴원 | N32: =O32-C32 -> 91 | O32: 45390 | P32: 귀가
A33: 172 | C33: 45387 | D33: 남 | E33: 권금호 | F33: 680228-1 | G33: 자의입원 | H33: 정신 | I33: 해상병원 | J33: 최리선 | L33: 우울증 | M33: 퇴원 | N33: =O33-C33 -> 4 | O33: 45391 | P33: 귀가
A34: 124 | C34: 45321 | D34: 남 | E34: 정재창 | F34: 670807-1 | G34: 자의입원 | H34: 알코올 | I34: 해상병원 | J34: 최리선 | L34: 알코올의존 | M34: 퇴원 | N34: =O34-C34 -> 73 | O34: 45394 | P34: 귀가 | Q34: 7/10 재원확인
A35: 113 | B35: =MONTH(C35) -> 1 | C35: 45305 | D35: 남 | E35: 박준후 | F35: 770712-1 | G35: 응급입원 | H35: 정신 | I35: 김포다은병원 | J35: 최리선 | L35: 우울증, 충동조절장애 | M35: 퇴원 | N35: =O35-C35 -> 92 | O35: 45397 | P35: 시설연계
A36: 147 | B36: =MONTH(C36) -> 2 | C36: 45348 | D36: 남 | E36: 방대수 | F36: 601209-1 | G36: 자의입원 | H36: 정신 | I36: 라엘정신건강의학과 | J36: 최리선 | L36: 조울증 | M36: 퇴원 | N36: =O36-C36 -> 50 | O36: 45398 | P36: 귀가 | Q36: 수급자, 스스로 방얻을 예정
A37: 134 | B37: =MONTH(C37) -> 2 | C37: 45330 | D37: 남 | E37: 조윤석 | F37: 770929-1 | G37: 자의입원 | H37: 알코올 | I37: 라엘정신건강의학과 | J37: 조국일 | L37: 알코올의존 | M37: 퇴원 | N37: =O37-C37 -> 69 | O37: 45399 | P37: 재입원
A38: 170 | C38: 45384 | D38: 남 | E38: 전민석 | F38: 650817-1 | G38: 자의입원 | H38: 알코올 | I38: 동부병원해독센터 | M38: 퇴원 | N38: =O38-C38 -> 15 | O38: 45399 | P38: 연락두절
A39: 97 | B39: =MONTH(C39) -> 12 | C39: 45267 | D39: 남 | E39: 최용화 | F39: 810908-1 | I39: 김포다은병원 | M39: 퇴원 | N39: =O39-C39 -> 134 | O39: 45401 | P39: 연락두절
A40: 166 | C40: 45378 | D40: 남 | E40: 양인수 | F40: 740518-1 | G40: 자의입원 | H40: 알코올 | I40: 라엘마음병원 | J40: 조국일 | L40: 알코올의존 | M40: 퇴원 | N40: =O40-C40 -> 26 | O40: 45404 | P40: 재노숙
...

Sheet 입원현황
B1: 월 | C1: 입원날짜 | D1: 성별 | E1: 대상자명 | F1: 생년월일 | G1: 입원형태 | H1: 질환명 | I1: 병원명 | J1: 담당자 | K1: 사례관리담당자 | L1: 진단명 | M1: 입원여부 | N1: 입원기간 | O1: 퇴원일 | P1: 퇴원 후 연계 | Q1: EMS | R1: 입원구 | S1: 비고
A2: 8 | B2: =MONTH(C2) -> 1 | C2: 46031 | D2: 남 | E2: 최성웅 | F2: 830701-1 | G2: 자의입원 | H2: 정신 | I2: 라엘정신건강의학과 | J2: 최리선 | K2: 안영호 | L2: 조현병 | M2: 퇴원 | N2: =O2-C2 -> 5 | O2: 46036 | P2: 재입원
A3: 12 | B3: =MONTH(C3) -> 1 | C3: 46038 | D3: 남 | E3: 남기훈 | F3: 810814-1 | G3: 자의입원 | H3: 알코올 | I3: 백암병원 | J3: 최리선 | K3: 최리선 | L3: 알코올의준 | M3: 퇴원 | N3: =O3-C3 -> 6 | O3: 46044 | P3: 체포 및 수감
A4: 10 | B4: =MONTH(C4) -> 1 | C4: 46036 | D4: 남 | E4: 최성웅 | F4: 830701-1 | G4: 자의입원 | H4: 정신 | I4: 백암병원 | J4: 안영호 | K4: 안영호 | L4: 강박장애 | M4: 퇴원 | N4: =O4-C4 -> 20 | O4: 46056 | P4: 재입원
A5: 11 | B5: =MONTH(C5) -> 1 | C5: 46038 | D5: 남 | E5: 전만춘 | F5: 591116-1 | G5: 응급입원 | H5: 정신 | I5: 도은병원 | J5: 임종혁 | K5: 마명철 | L5: 조울증 | M5: 퇴원 | N5: =O5-C5 -> 19 | O5: 46057 | P5: 사망
A6: 14 | B6: =MONTH(C6) -> 1 | C6: 46044 | D6: 남 | E6: 임진성 | F6: 880225-1 | G6: 자의입원 | H6: 알코올 | I6: 라엘마음병원 | J6: 안영호 | K6: 안영호 | L6: 알코올의존 | M6: 퇴원 | N6: =O6-C6 -> 13 | O6: 46057 | P6: 재노숙
A7: 3 | B7: =MONTH(C7) -> 1 | C7: 46029 | D7: 남 | E7: 김종수 | F7: 730311-1 | G7: 응급입원 | H7: 알코올 | I7: 김포다은병원 | J7: 안영호 | K7: 안영호 | L7: 알코올의존 | M7: 퇴원 | N7: =O7-C7 -> 30 | O7: 46059 | P7: 재노숙
A8: 30 | B8: =MONTH(C8) -> 2 | C8: 46058 | D8: 남 | E8: 김민호 | F8: 011025-1 | G8: 자의입원 | H8: 정신 | I8: 김포다은병원 | J8: 김영민 | K8: 김영민 | L8: 우울에피소드 불안 | M8: 퇴원 | N8: =O8-C8 -> 1 | O8: 46059 | P8: 재노숙
A9: 22 | B9: =MONTH(C9) -> 1 | C9: 46049 | D9: 남 | E9: 박기태 | F9: 860312-1 | G9: 자의입원 | H9: 알코올 | I9: 동부시립병원 해독센터 | J9: 임종혁 | K9: 임종혁 | L9: 알코올의존 | M9: 퇴원 | N9: =O9-C9 -> 24 | O9: 46073 | P9: 연락두절
A10: 15 | B10: =MONTH(C10) -> 1 | C10: 46045 | D10: 남 | E10: 유선태 | F10: 651208-1 | G10: 자의입원 | H10: 알코올 | I10: 해상병원 | J10: 임종혁 | L10: 우울증, 알코올의존 | M10: 퇴원 | N10: =O10-C10 -> 41 | O10: 46086 | P10: 전원 | S10: 김포한강요양병원
A11: 33 | B11: =MONTH(C11) -> 2 | C11: 46058 | D11: 남 | E11: 한현석 | F11: 800624-1 | G11: 자의입원 | H11: 정신 | I11: 백암병원 | J11: 박상준 | K11: 박상준 | L11: 자살사고 | M11: 퇴원 | N11: =O11-C11 -> 32 | O11: 46090
A12: 48 | B12: =MONTH(C12) -> 3 | C12: 46085 | D12: 남 | E12: 안영상 | F12: 950419-1 | G12: 자의입원 | H12: 정신 | I12: 라엘정신건강의학과 | J12: 임종혁 | K12: 임종혁 | L12: 우울, 불안, 자살사고 | M12: 입원중 | N12: =O12-C12 -> 8 | O12: 46093 | P12: 재입원 | S12: 3/13 해상병원 응급입원
A13: 1 | B13: =MONTH(C13) -> 1 | C13: 46024 | D13: 남 | E13: 임웅택 | F13: 710402-1 | G13: 자의입원 | H13: 정신 | I13: 라엘마음병원 | J13: 조국일 | K13: 조국일 | L13: 조현병 | M13: 입원중 | N13: =O13-C13 -> -46024
A14: 2 | B14: =MONTH(C14) -> 1 | C14: 46027 | D14: 남 | E14: 김승정 | F14: 741229-1 | G14: 응급입원 | H14: 정신 | I14: 은평병원 | J14: 조국일 | K14: 조국일 | L14: 조현병 | M14: 입원중 | N14: =O14-C14 -> -46027
A15: 4 | B15: =MONTH(C15) -> 1 | C15: 46029 | D15: 남 | E15: 김남수 | F15: 670207-1 | G15: 자의입원 | H15: 알코올 | I15: 라엘정신건강의학과 | J15: 임종혁 | K15: 임종혁 | L15: 알코올의존 | M15: 입원중 | N15: =O15-C15 -> -46029
A16: 5 | B16: =MONTH(C16) -> 1 | C16: 46029 | D16: 남 | E16: 서교순 | F16: 620706-1 | G16: 자의입원 | H16: 알코올 | I16: 라엘정신건강의학과 | J16: 임종혁 | K16: 마명철 | L16: 알코올의존 | M16: 입원중 | N16: =O16-C16 -> -46029
A17: 6 | B17: =MONTH(C17) -> 1 | C17: 46029 | D17: 남 | E17: 박정열 | F17: 601125-1 | G17: 자의입원 | H17: 알코올 | I17: 해상병원 | J17: 조국일 | K17: 조국일 | L17: 알코올의존 | M17: 입원중 | N17: =O17-C17 -> -46029
A18: 7 | B18: =MONTH(C18) -> 1 | C18: 46030 | D18: 여 | E18: 이형주 | F18: 700909-2 | G18: 보호진단 | H18: 정신 | I18: 백암병원 | J18: 안영호 | K18: 최리선 | L18: 조현병 | M18: 입원중 | N18: =O18-C18 -> -46030
A19: 9 | B19: =MONTH(C19) -> 1 | C19: 46035 | D19: 남 | E19: 정재창 | F19: 670807-1 | G19: 보호진단 | H19: 알코올 | I19: 김포다은병원 | J19: 최리선 | K19: 최리선 | L19: 알코올의존 | M19: 입원중 | N19: =O19-C19 -> -46035
A20: 13 | B20: =MONTH(C20) -> 1 | C20: 46042 | D20: 남 | E20: 정기풍 | F20: 760320-1 | G20: 응급입원 | H20: 알코올 | I20: 라엘마음병원 | J20: 안영호 | K20: 안영호 | L20: 알코올의존 | M20: 입원중 | N20: =O20-C20 -> -46042
A21: 16 | B21: =MONTH(C21) -> 1 | C21: 46048 | D21: 남 | E21: 문정호 | F21: 820818-1 | G21: 응급입원 | H21: 정신 | I21: 동안성병원 | J21: 안영호 | K21: 조국일 | L21: 조현병, 알코올의존 | M21: 입원중 | N21: =O21-C21 -> -46048
A22: 25 | B22: =MONTH(C22) -> 1 | C22: 46049 | D22: 남 | E22: 양인수 | F22: 740518-1 | G22: 응급입원 | H22: 알코올 | I22: 라엘마음병원 | J22: 안영호 | K22: 조국일 | L22: 알코올의존 | M22: 입원중 | N22: =O22-C22 -> -46049
A23: 17 | B23: =MONTH(C23) -> 1 | C23: 46050 | D23: 남 | E23: 최종은 | F23: 690301-1 | G23: 보호진단 | H23: 알코올 | I23: 도은병원 | J23: 김영민 | K23: 김영민 | L23: 알코올의존 | M23: 입원중 | N23: =O23-C23 -> -46050
A24: 18 | B24: =MONTH(C24) -> 1 | C24: 46050 | D24: 남 | E24: 손성호 | F24: 710515-1 | G24: 자의입원 | H24: 정신 | I24: 도은병원 | J24: 임종혁 | L24: 조현병, 알코올의존 | M24: 입원중 | N24: =O24-C24 -> -46050
A25: 19 | B25: =MONTH(C25) -> 1 | C25: 46050 | D25: 남 | E25: 홍순창 | F25: 680824-1 | G25: 보호진단 | H25: 알코올 | I25: 라엘마음병원 | J25: 최리선 | K25: 박상준 | L25: 알코올의존 | M25: 입원중 | N25: =O25-C25 -> -46050
